<?xml version='1.0' encoding='utf-8'?>
<robot name="DR01_v101">
  <link name="SACRUM">
    <inertial>
      <origin xyz="0.0010 -2.1928E-05 -0.0252" />
      <mass value="3.2422" />
      <inertia ixx="0.0101" ixy="-8.7E-07" ixz="-0.0002" iyy="0.0055" iyz="-2.8E-07" izz="0.0100" />
    </inertial>
    <visual>
      <geometry>
        <mesh filename="../meshes/SACRUM.dae" />
      </geometry>
    </visual>
  </link>

  <link name="ILIUM_R">
    <inertial>
      <origin xyz="-0.0752 -0.0297 0.0117" />
      <mass value="1.6695" />
      <inertia ixx="0.0031" ixy="-0.0003" ixz="-0.0014" iyy="0.0064" iyz="-0.0003" izz="0.0054" />
    </inertial>
    <visual>
      <geometry>
        <mesh filename="../meshes/ILIUM_R.dae" />
      </geometry>
    </visual>
    <collision>
      <origin xyz="-0.129 -0.032 0" rpy="0 1.57 0" />
      <geometry>
        <cylinder length="0.02" radius="0.046" />
      </geometry>
    </collision>
  </link>

  <joint name="Hip_Z_R" type="revolute">
    <origin xyz="0 -0.045 -0.1505" />
    <parent link="SACRUM" />
    <child link="ILIUM_R" />
    <axis xyz="0 0 -1" />
    <limit lower="-0.21" upper="0.216" effort="84" velocity="7.85" />
    <dynamics damping="0" friction="0" />
  </joint>

  <link name="ISCHIUM_R">
    <inertial>
      <origin xyz="-0.0061 0.0083 -0.0004" />
      <mass value="1.489" />
      <inertia ixx="0.0012" ixy="-8.78E-05" ixz="0" iyy="0.0022" iyz="-7.68E-06" izz="0.0017" />
    </inertial>
    <visual>
      <geometry>
        <mesh filename="../meshes/ISCHIUM_R.dae" />
      </geometry>
    </visual>
  </link>

  <joint name="Hip_X_R" type="revolute">
    <origin xyz="0 -0.0325 0" />
    <parent link="ILIUM_R" />
    <child link="ISCHIUM_R" />
    <axis xyz="-1 0 0" />
    <limit lower="-0.204" upper="0.370" effort="84" velocity="7.85" />
    <dynamics damping="0" friction="0" />
  </joint>

  <link name="THIGH_R">
    <inertial>
      <origin xyz="0.0048 -0.0279 -0.0394" />
      <mass value="3.5319" />
      <inertia ixx="0.0286" ixy="-0.0001" ixz="0.0018" iyy="0.0293" iyz="0.0014" izz="0.0059" />
    </inertial>
    <visual>
      <geometry>
        <mesh filename="../meshes/THIGH_R.dae" />
      </geometry>
    </visual>
    <collision>
      <origin xyz="0.03 -0.02 -0.18" />
      <geometry>
        <cylinder length="0.23" radius="0.06" />
      </geometry>
    </collision>
    <collision>
      <origin xyz="0 -0.04 0" rpy="1.57 0 0" />
      <geometry>
        <cylinder length="0.10" radius="0.072" />
      </geometry>
    </collision>
  </link>

  <joint name="Hip_Y_R" type="revolute">
    <origin xyz="0 -0.0432 0" />
    <parent link="ISCHIUM_R" />
    <child link="THIGH_R" />
    <axis xyz="0 1 0" />
    <limit lower="-2.215" upper="0.125" effort="84" velocity="7.85" />
    <dynamics damping="0" friction="0" />
  </joint>

  <link name="SHANK_R">
    <inertial>
      <origin xyz="0.0106 -0.0096 -0.0512" />
      <mass value="2.7397" />
      <inertia ixx="0.0149" ixy="-0.0003" ixz="0.0006" iyy="0.0146" iyz="0.0007" izz="0.0032" />
    </inertial>
    <visual>
      <geometry>
        <mesh filename="../meshes/SHANK_R.dae" />
      </geometry>
    </visual>
    <collision>
      <origin xyz="0.02 0 -0.18" rpy="0 0.3 0" />
      <geometry>
        <cylinder length="0.14" radius="0.02" />
      </geometry>
    </collision>
    <collision>
      <origin xyz="0.03 0 -0.08" rpy="0 1.57 0" />
      <geometry>
        <cylinder length="0.06" radius="0.038" />
      </geometry>
    </collision>
  </link>

  <joint name="Knee_R" type="revolute">
    <origin xyz="0 0 -0.3" />
    <parent link="THIGH_R" />
    <child link="SHANK_R" />
    <axis xyz="0 1 0" />
    <limit lower="0.34" upper="2.70" effort="180" velocity="12" />
    <dynamics damping="0" friction="0" />
  </joint>

  <link name="ASTRAGALUS_R">
    <inertial>
      <origin xyz="-0.0144 -3.454E-05 0.0058" />
      <mass value="0.0686" />
      <inertia ixx="8.86E-06" ixy="-2E-08" ixz="5.49E-07" iyy="0" iyz="4E-08" izz="0" />
    </inertial>
    <visual>
      <geometry>
        <mesh filename="../meshes/ASTRAGALUS.dae" />
      </geometry>
    </visual>
  </link>

  <joint name="Ankle_Y_R" type="revolute">
    <origin xyz="0 0 -0.3" />
    <parent link="SHANK_R" />
    <child link="ASTRAGALUS_R" />
    <axis xyz="0 1 0" />
    <limit lower="-1.0" upper="0.19" effort="200" velocity="14.65" />
    <dynamics damping="0" friction="0" />
  </joint>

  <link name="FOOT_R">
    <inertial>
      <origin xyz="-5.1084E-10 -0.0011 -0.0247" />
      <mass value="0.2330" />
      <inertia ixx="0.0001" ixy="-2.5096E-10" ixz="8.0022E-13" iyy="0.0006" iyz="3.92E-06" izz="0.0007" />
    </inertial>
    <visual>
      <geometry>
        <mesh filename="../meshes/FOOT_R.dae" />
      </geometry>
    </visual>
  </link>

  <joint name="Ankle_X_R" type="revolute">
    <parent link="ASTRAGALUS_R" />
    <child link="FOOT_R" />
    <axis xyz="-1 0 0" />
    <limit lower="-0.20" upper="0.24" effort="200" velocity="14.65" />
    <dynamics damping="0" friction="0" />
  </joint>

  <link name="TIPTOE_R">
    <inertial>
      <origin xyz="0.001 0.001 -0.0053" />
      <mass value="0.1929" />
      <inertia ixx="0.0001" ixy="0" ixz="0" iyy="0.0008" iyz="0" izz="0.0009" />
    </inertial>
    <collision>
      <origin xyz="0.02 0 -0.01" />
      <geometry>
        <box size="0.24 0.08 0.03" />
      </geometry>
    </collision>
  </link>

  <joint name="Ankle_Z_R" type="fixed">
    <origin xyz="0 0 -0.031" />
    <parent link="FOOT_R" />
    <child link="TIPTOE_R" />
  </joint>

  <link name="ILIUM_L">
    <inertial>
      <origin xyz="-0.0752 0.0297 0.0118" />
      <mass value="1.6675" />
      <inertia ixx="0.0031" ixy="0.0003" ixz="-0.0014" iyy="0.0064" iyz="0.0003" izz="0.0054" />
    </inertial>
    <visual>
      <geometry>
        <mesh filename="../meshes/ILIUM_L.dae" />
      </geometry>
    </visual>
    <collision>
      <origin xyz="-0.129 0.032 0" rpy="0 1.57 0" />
      <geometry>
        <cylinder length="0.02" radius="0.046" />
      </geometry>
    </collision>
  </link>

  <joint name="Hip_Z_L" type="revolute">
    <origin xyz="0 0.045 -0.1505" />
    <parent link="SACRUM" />
    <child link="ILIUM_L" />
    <axis xyz="0 0 1" />
    <limit lower="-0.21" upper="0.21" effort="84" velocity="7.85" />
    <dynamics damping="0" friction="0" />
  </joint>

  <link name="ISCHIUM_L">
    <inertial>
      <origin xyz="-0.0061 -0.0083 -0.0005" />
      <mass value="1.489" />
      <inertia ixx="0.0012" ixy="0.0001" ixz="0" iyy="0.0022" iyz="0" izz="0.0017" />
    </inertial>
    <visual>
      <geometry>
        <mesh filename="../meshes/ISCHIUM_L.dae" />
      </geometry>
    </visual>
  </link>

  <joint name="Hip_X_L" type="revolute">
    <origin xyz="0 0.0325 0" />
    <parent link="ILIUM_L" />
    <child link="ISCHIUM_L" />
    <axis xyz="1 0 0" />
    <limit lower="-0.21" upper="0.370" effort="84" velocity="7.85" />
    <dynamics damping="0" friction="0" />
  </joint>

  <link name="THIGH_L">
    <inertial>
      <origin xyz="0.0048 0.0299 -0.0397" />
      <mass value="3.5416" />
      <inertia ixx="0.0287" ixy="0.0001" ixz="0.0018" iyy="0.0295" iyz="-0.0014" izz="0.0059" />
    </inertial>
    <visual>
      <geometry>
        <mesh filename="../meshes/THIGH_L.dae" />
      </geometry>
    </visual>
    <collision>
      <origin xyz="0.03 0.02 -0.18" />
      <geometry>
        <cylinder length="0.23" radius="0.06" />
      </geometry>
    </collision>
    <collision>
      <origin xyz="0 0.04 0" rpy="1.57 0 0" />
      <geometry>
        <cylinder length="0.10" radius="0.072" />
      </geometry>
    </collision>
  </link>

  <joint name="Hip_Y_L" type="revolute">
    <origin xyz="0 0.0432 0" />
    <parent link="ISCHIUM_L" />
    <child link="THIGH_L" />
    <axis xyz="0 1 0" />
    <limit lower="-2.207" upper="0.462" effort="84" velocity="7.85" />
    <dynamics damping="0" friction="0" />
  </joint>

  <link name="SHANK_L">
    <inertial>
      <origin xyz="0.0109 0.0095 -0.0522" />
      <mass value="2.7463" />
      <inertia ixx="0.0150" ixy="0.0003" ixz="0.0006" iyy="0.0146" iyz="-0.0007" izz="0.0033" />
    </inertial>
    <visual>
      <geometry>
        <mesh filename="../meshes/SHANK_L.dae" />
      </geometry>
    </visual>
    <collision>
      <origin xyz="0.02 0 -0.18" rpy="0 0.3 0" />
      <geometry>
        <cylinder length="0.14" radius="0.02" />
      </geometry>
    </collision>
    <collision>
      <origin xyz="0.03 0 -0.08" rpy="0 1.57 0" />
      <geometry>
        <cylinder length="0.06" radius="0.038" />
      </geometry>
    </collision>
  </link>

  <joint name="Knee_L" type="revolute">
    <origin xyz="0 0 -0.3" />
    <parent link="THIGH_L" />
    <child link="SHANK_L" />
    <axis xyz="0 1 0" />
    <limit lower="0.30" upper="2.65" effort="180" velocity="12" />
    <dynamics damping="0" friction="0" />
  </joint>

  <link name="ASTRAGALUS_L">
    <inertial>
      <origin xyz="-0.0144 -3.4496E-05 0.0058" />
      <mass value="0.0686" />
      <inertia ixx="8.86E-06" ixy="-2E-08" ixz="5.49E-06" iyy="0" iyz="4E-08" izz="0" />
    </inertial>
    <visual>
      <geometry>
        <mesh filename="../meshes/ASTRAGALUS.dae" />
      </geometry>
    </visual>
  </link>

  <joint name="Ankle_Y_L" type="revolute">
    <origin xyz="0 0 -0.3" />
    <parent link="SHANK_L" />
    <child link="ASTRAGALUS_L" />
    <axis xyz="0 1 0" />
    <limit lower="-1.0" upper="0.154" effort="200" velocity="14.65" />
    <dynamics damping="0" friction="0" />
  </joint>

  <link name="FOOT_L">
    <inertial>
      <origin xyz="1.1755E-08 0.0011 -0.0247" />
      <mass value="0.2330" />
      <inertia ixx="0.0001" ixy="-2.5096E-10" ixz="-8.0022E-13" iyy="0.0006" iyz="-3.9216E-06" izz="0.0007" />
    </inertial>
    <visual>
      <geometry>
        <mesh filename="../meshes/FOOT_L.dae" />
      </geometry>
    </visual>
  </link>

  <joint name="Ankle_X_L" type="revolute">
    <parent link="ASTRAGALUS_L" />
    <child link="FOOT_L" />
    <axis xyz="1 0 0" />
    <limit lower="-0.207" upper="0.23" effort="200" velocity="14.65" />
    <dynamics damping="0" friction="0" />
  </joint>

  <link name="TIPTOE_L">
    <inertial>
      <origin xyz="0 0 -0.0053" />
      <mass value="0.1929" />
      <inertia ixx="0.0001" ixy="0" ixz="0" iyy="0.0008" iyz="0" izz="0.0009" />
    </inertial>
    <collision>
      <origin xyz="0.02 0 -0.01" />
      <geometry>
        <box size="0.24 0.08 0.03" />
      </geometry>
    </collision>
  </link>

  <joint name="Ankle_Z_L" type="fixed">
    <origin xyz="0 0 -0.031" />
    <parent link="FOOT_L" />
    <child link="TIPTOE_L" />
  </joint>

  <link name="TORSO">
    <inertial>
      <origin xyz="0.0027 0.0001 0.1822" />
      <mass value="15.944" />
      <inertia ixx="0.1635" ixy="-0.0001" ixz="-0.0004" iyy="0.0802" iyz="0" izz="0.1156" />
    </inertial>
    <visual>
      <geometry>
        <mesh filename="../meshes/TORSO.dae" />
      </geometry>
    </visual>
    <collision>
      <origin xyz="0 0 0.15" />
      <geometry>
        <box size="0.2 0.31 0.48" />
      </geometry>
    </collision>
    <collision>
      <origin xyz="0 0 0.57" />
      <geometry>
        <sphere radius="0.08" />
      </geometry>
    </collision> 
    <collision>
      <origin xyz="0.04 0 0.51" rpy="0 -0.22 0" />
      <geometry>
        <cylinder length="0.08" radius="0.045" />
      </geometry>
    </collision>
  </link>

  <joint name="Waist" type="revolute">
    <origin xyz="0 0 0.0465" />
    <parent link="SACRUM" />
    <child link="TORSO" />
    <axis xyz="0 0 1" />
    <limit lower="-0.698" upper="0.698" effort="84" velocity="7.85" />
    <dynamics damping="0" friction="0" />
  </joint>

  <link name="SCAPULA_R">
    <inertial>
      <origin xyz="-0.0363 -0.0004 0.0520"  />
      <mass value="0.9695" />
      <inertia ixx="0.0008" ixy="0" ixz="0.0001" iyy="0.0010" iyz="0" izz="0.0009" />
    </inertial>
    <visual>
      <geometry>
        <mesh filename="../meshes/SCAPULA_R.dae" />
      </geometry>
    </visual>
  </link>

  <joint name="Shoulder_Z_R" type="revolute">
    <origin xyz="0 -0.1725 0.3458" />
    <parent link="TORSO" />
    <child link="SCAPULA_R" />
    <axis xyz="0 0 -1" />
    <limit lower="-0.366" upper="0.366" effort="100" velocity="4.1" />
    <dynamics damping="0" friction="0" />
  </joint>

  <link name="SHOULDER_R">
    <inertial>
      <origin xyz="0.0445 0.0362 0.0004"  />
      <mass value="0.9738" />
      <inertia ixx="0.0010" ixy="-0.0001" ixz="0" iyy="0.0008" iyz="0" izz="0.0010" />
    </inertial>
    <visual>
      <geometry>
        <mesh filename="../meshes/SHOULDER_R.dae" />
      </geometry>
    </visual>
  </link>

  <joint name="Shoulder_X_R" type="revolute">
    <origin xyz="0.0473 0 0" />
    <parent link="SCAPULA_R" />
    <child link="SHOULDER_R" />
    <axis xyz="-1 0 0" />
    <limit lower="-0.366" upper="0.366" effort="100" velocity="4.1" />
    <dynamics damping="0" friction="0" />
  </joint>

  <link name="UPPERARM_R">
    <inertial>
      <origin xyz="-0.0047 -0.0690 -0.0353"  />
      <mass value="1.4558" />
      <inertia ixx="0.0109" ixy="-0.0006" ixz="-0.0009" iyy="0.0097" iyz="-0.0020" izz="0.0036" />
    </inertial>
    <visual>
      <geometry>
        <mesh filename="../meshes/UPPERARM_R.dae" />
      </geometry>
    </visual>
    <collision>
      <origin xyz="0 0 -0.125"  />
      <geometry>
        <box size="0.075 0.07 0.25" />
      </geometry>
    </collision> 
    <collision>
      <origin xyz="0 0 0" rpy="1.57 0 0" />
      <geometry>
        <cylinder length="0.08" radius="0.045" />
      </geometry>
    </collision>
  </link>

  <joint name="Shoulder_Y_R" type="revolute">
    <origin xyz="0 -0.1119 0" />
    <parent link="SHOULDER_R" />
    <child link="UPPERARM_R" />
    <axis xyz="0 1 0" />
    <limit lower="-1.788" upper="0.714" effort="28" velocity="14.65" />
    <dynamics damping="0" friction="0" />
  </joint>

  <link name="FOREARM_R">
    <inertial>
      <origin xyz="0.1028 -3.8955E-05 -0.0192"  />
      <mass value="0.8906" />
      <inertia ixx="0.0068" ixy="-0.0012" ixz="0.0015" iyy="0.0057" iyz="0.0029" izz="0.0035" />
    </inertial>
    <visual>
      <geometry>
        <mesh filename="../meshes/FOREARM_R.dae" />
      </geometry>
    </visual>
    <collision>
      <origin xyz="0.1 0 -0.02" rpy="0 1.57 0" />
      <geometry>
        <cylinder length="0.085" radius="0.033" />
      </geometry>
    </collision> 
  </link>

  <joint name="Elbow_R" type="revolute">
    <origin xyz="0 0 -0.25" />
    <parent link="UPPERARM_R" />
    <child link="FOREARM_R" />
    <axis xyz="0 1 0" />
    <limit lower="-1.274" upper="0.923" effort="28" velocity="14.65" />
    <dynamics damping="0" friction="0" />
  </joint>

  <link name="RADIOCARPAL_R">
    <inertial>
      <origin xyz="0.0467 -2.5524E-05 0.0015"  />
      <mass value="0.5548" />
      <inertia ixx="0.0003" ixy="0" ixz="0" iyy="0.0003" iyz="0" izz="0.0004" />
    </inertial>
    <visual>
      <geometry>
        <mesh filename="../meshes/RADIOCARPAL.dae" />
      </geometry>
    </visual>
  </link>

  <joint name="Wrist_X_R" type="revolute">
    <origin xyz="0.1875 0 -0.02" />
    <parent link="FOREARM_R" />
    <child link="RADIOCARPAL_R" />
    <axis xyz="-1 0 0" />
    <limit lower="-0.366" upper="0.366" effort="28" velocity="4.1" />
  </joint>

  <link name="LUNCATE_R">
    <inertial>
      <origin xyz="0.0285 -0.0203 0.0188"  />
      <mass value="0.8817" />
      <inertia ixx="0" ixy="0" ixz="0" iyy="0.0001" iyz="0" izz="0.0001" />
    </inertial>
    <visual>
      <geometry>
        <mesh filename="../meshes/LUNCATE_R.dae" />
      </geometry>
    </visual>
    <collision>
      <geometry>
        <cylinder length="0.062" radius="0.027" />
      </geometry>
    </collision> 
  </link>

  <joint name="Wrist_Z_R" type="revolute">
    <parent link="RADIOCARPAL_R" />
    <child link="LUNCATE_R" />
    <axis xyz="0 0 -1" />
    <limit lower="-0.366" upper="0.366" effort="28" velocity="4.1" />
  </joint>

  <link name="TRIQUETRUM_R">
    <inertial>
      <origin xyz="0.0489 -0.0023 0.0010"  />
      <mass value="1.1640" />
      <inertia ixx="0.0036" ixy="0.0014" ixz="-0.0001" iyy="0.0065" iyz="-0.0001" izz="0.0076" />
    </inertial>
    <visual>
      <geometry>
        <mesh filename="../meshes/TRIQUETRUM_R.dae" />
      </geometry>
    </visual>
    <collision>
      <origin  rpy="1.57 0 0" />
      <geometry>
        <cylinder length="0.062" radius="0.027" />
      </geometry>
    </collision> 
    <collision>
      <origin xyz="0.115 0 0" rpy="1.57 0 0" />
      <geometry>
        <box size="0.16 0.073 0.035" />
      </geometry>
    </collision> 
    <collision>
      <origin xyz="0.115 0.045 0.03" rpy="0 -0.36 0.6" />
      <geometry>
        <box size="0.088 0.015 0.015" />
      </geometry>
    </collision> 
  </link>

  <joint name="Wrist_Y_R" type="revolute">
    <origin xyz="0.057 0 0" />
    <parent link="LUNCATE_R" />
    <child link="TRIQUETRUM_R" />
    <axis xyz="0 1 0" />
    <limit lower="-0.766" upper="0.766" effort="28" velocity="4.1" />
  </joint>

  <link name="HAND_R">
    <inertial>
      <origin xyz="-0.0243 0.0105 0.0031" />
      <mass value="0.2589" />
      <inertia ixx="7.6765E-05" ixy="-2.4040E-06" ixz="-2.1977E-06" iyy="0.0001" iyz="-2.7614E-08" izz="8.6697E-05" />
    </inertial>
  </link>

  <joint name="Wrist_Fix_R" type="fixed">
    <origin xyz="0.1535 0 0" />
    <parent link="TRIQUETRUM_R" />
    <child link="HAND_R" />
  </joint>

  <link name="WRIST_CAMERA_R">
    <inertial>
      <origin xyz="0.0099 -7.1416E-05 0" />
      <mass value="0.1" />
      <inertia ixx="0.0001" ixy="0.0001" ixz="0.0001" iyy="0.0001" iyz="0.0001" izz="0.0001" />
    </inertial>
  </link>

  <joint name="Bracelet_R" type="fixed">
    <origin xyz="0.0430 -0.0560 0" rpy="1.5708 0 0" />
    <parent link="TRIQUETRUM_R" />
    <child link="WRIST_CAMERA_R" />
  </joint>

  <link name="SCAPULA_L">
    <inertial>
      <origin xyz="-0.0363 0.0002 0.0520"  />
      <mass value="0.9695" />
      <inertia ixx="0.0008" ixy="0" ixz="0.0001" iyy="0.0010" iyz="0" izz="0.0009" />
    </inertial>
    <visual>
      <geometry>
        <mesh filename="../meshes/SCAPULA_L.dae" />
      </geometry>
    </visual>
  </link>

  <joint name="Shoulder_Z_L" type="revolute">
    <origin xyz="0 0.1725 0.3458" />
    <parent link="TORSO" />
    <child link="SCAPULA_L" />
    <axis xyz="0 0 1" />
    <limit lower="-0.366" upper="0.366" effort="100" velocity="4.1" />
    <dynamics damping="0" friction="0" />
  </joint>

  <link name="SHOULDER_L">
    <inertial>
      <origin xyz="0.0445 -0.0362 0.0003"  />
      <mass value="0.9738" />
      <inertia ixx="0.0010" ixy="0.0001" ixz="0" iyy="0.0008" iyz="0" izz="0.0010" />
    </inertial>
    <visual>
      <geometry>
        <mesh filename="../meshes/SHOULDER_L.dae" />
      </geometry>
    </visual>
  </link>

  <joint name="Shoulder_X_L" type="revolute">
    <origin xyz="0.0473 0 0" />
    <parent link="SCAPULA_L" />
    <child link="SHOULDER_L" />
    <axis xyz="1 0 0" />
    <limit lower="-0.366" upper="0.366" effort="100" velocity="4.1" />
    <dynamics damping="0" friction="0" />
  </joint>

  <link name="UPPERARM_L">
    <inertial>
      <origin xyz="-0.0049 0.0691 -0.0349"  />
      <mass value="1.4547" />
      <inertia ixx="0.0107" ixy="0.0006" ixz="-0.0009" iyy="0.0096" iyz="0.0020" izz="0.0035" />
    </inertial>
    <visual>
      <geometry>
        <mesh filename="../meshes/UPPERARM_L.dae" />
      </geometry>
    </visual>
    <collision>
      <origin xyz="0 0 -0.125"  />
      <geometry>
        <box size="0.075 0.07 0.25" />
      </geometry>
    </collision> 
    <collision>
      <origin xyz="0 0 0" rpy="1.57 0 0" />
      <geometry>
        <cylinder length="0.08" radius="0.045" />
      </geometry>
    </collision>
  </link>

  <joint name="Shoulder_Y_L" type="revolute">
    <origin xyz="0 0.1121 0" />
    <parent link="SHOULDER_L" />
    <child link="UPPERARM_L" />
    <axis xyz="0 1 0" />
    <limit lower="-1.788" upper="0.714" effort="28" velocity="14.65" />
    <dynamics damping="0" friction="0" />
  </joint>

  <link name="FOREARM_L">
    <inertial>
      <origin xyz="0.1028 1.7857E-05 -0.0191"  />
      <mass value="0.8906" />
      <inertia ixx="0.0003" ixy="0" ixz="0.0001" iyy="0.0009" iyz="0" izz="0.0009" />
    </inertial>
    <visual>
      <geometry>
        <mesh filename="../meshes/FOREARM_L.dae" />
      </geometry>
    </visual>
    <collision>
      <origin xyz="0.1 0 -0.02" rpy="0 1.57 0" />
      <geometry>
        <cylinder length="0.085" radius="0.033" />
      </geometry>
    </collision> 
  </link>

  <joint name="Elbow_L" type="revolute">
    <origin xyz="0 0 -0.25" />
    <parent link="UPPERARM_L" />
    <child link="FOREARM_L" />
    <axis xyz="0 1 0" />
    <limit lower="-1.274" upper="0.923" effort="28" velocity="14.65" />
    <dynamics damping="0" friction="0" />
  </joint>

  <link name="RADIOCARPAL_L">
    <inertial>
      <origin xyz="0.0467 7.7026E-05 0.0015"  />
      <mass value="0.5548" />
      <inertia ixx="0.0003" ixy="0" ixz="0" iyy="0.0003" iyz="0" izz="0.0004" />
    </inertial>
    <visual>
      <geometry>
        <mesh filename="../meshes/RADIOCARPAL.dae" />
      </geometry>
    </visual>
  </link>

  <joint name="Wrist_X_L" type="revolute">
    <origin xyz="0.1875 0 -0.02" />
    <parent link="FOREARM_L" />
    <child link="RADIOCARPAL_L" />
    <axis xyz="1 0 0" />
    <limit lower="-0.366" upper="0.366" effort="28" velocity="4.1" />
  </joint>

  <link name="LUNCATE_L">
    <inertial>
      <origin xyz="0.0285 0.0203 0.0188"  />
      <mass value="0.8817" />
      <inertia ixx="0.0001" ixy="-0.0001" ixz="0" iyy="0.0002" iyz="0" izz="0.0002" />
    </inertial>
    <visual>
      <geometry>
        <mesh filename="../meshes/LUNCATE_L.dae" />
      </geometry>
    </visual>
    <collision>
      <geometry>
        <cylinder length="0.062" radius="0.027" />
      </geometry>
    </collision> 
  </link>

  <joint name="Wrist_Z_L" type="revolute">
    <parent link="RADIOCARPAL_L" />
    <child link="LUNCATE_L" />
    <axis xyz="0 0 1" />
    <limit lower="-0.366" upper="0.366" effort="28" velocity="4.1" />
  </joint>

  <link name="TRIQUETRUM_L">
    <inertial>
      <origin xyz="0.0488 -0.0002 0.0011"  />
      <mass value="1.1604" />
      <inertia ixx="0.0006" ixy="0.0003" ixz="-0.0001" iyy="0.0041" iyz="0.0001" izz="0.0041" />
    </inertial>
    <visual>
      <geometry>
        <mesh filename="../meshes/TRIQUETRUM_L.dae" />
      </geometry>
    </visual>
    <collision>
      <origin xyz="0.115 0 0" rpy="1.57 0 0" />
      <geometry>
        <box size="0.16 0.073 0.035" />
      </geometry>
    </collision> 
    <collision>
      <origin xyz="0.115 -0.045 0.03" rpy="0 -0.36 -0.6" />
      <geometry>
        <box size="0.088 0.015 0.015" />
      </geometry>
    </collision> 
  </link>

  <joint name="Wrist_Y_L" type="revolute">
    <origin xyz="0.057 0 0" />
    <parent link="LUNCATE_L" />
    <child link="TRIQUETRUM_L" />
    <axis xyz="0 1 0" />
    <limit lower="-0.366" upper="0.366" effort="28" velocity="4.1" />
  </joint>

  <link name="HAND_L">
    <inertial>
      <origin xyz="-0.0243 -0.0105 0.0031" />
      <mass value="0.2589" />
      <inertia ixx="7.6764E-05" ixy="2.4042E-06" ixz="-2.1975E-06" iyy="0.0001" iyz="2.7056E-08" izz="8.6696E-05" />
    </inertial>
  </link>

  <joint name="Wrist_Fix_L" type="fixed">
    <origin xyz="0.1535 0 0" />
    <parent link="TRIQUETRUM_L" />
    <child link="HAND_L" />
  </joint>

  <link name="WRIST_CAMERA_L">
    <inertial>
      <origin xyz="-0.0016 -2.2687E-08 -0.0351" />
      <mass value="0.0407" />
      <inertia ixx="3.8657E-05" ixy="-1.1424E-11" ixz="1.0347E-07" iyy="2.7211E-05" iyz="-1.5348E-11" izz="1.2869E-05" />
    </inertial>
  </link>

  <joint name="Bracelet_L" type="fixed">
    <origin xyz="0.0430 0.0560 0" rpy="-1.5708 0 0" />
    <parent link="TRIQUETRUM_L" />
    <child link="WRIST_CAMERA_L" />
  </joint>

  <link name="CHEST_CAMERA">
    <inertial>
      <mass value="0.01" />
      <inertia ixx="2E-5" ixy="1E-13" ixz="-1E-07" iyy="2E-5" iyz="1E-13" izz="2E-5" />
    </inertial>
  </link>

  <joint name="Torso_2_Cam" type="fixed">
    <origin xyz="0.1311 0 0.2134" rpy="0 0.9076 0" />
    <parent link="TORSO" />
    <child link="CHEST_CAMERA" />
  </joint>

</robot>
