<?xml version='1.0' encoding='utf-8'?>
<robot name="CL201">
  <link name="base_link">
    <inertial>
      <origin xyz="0.1482 0.0042 -0.0387"  />
      <mass value="10.781" />
      <inertia ixx="0.1920" ixy="-0.0006" ixz="-0.0032" iyy="0.1698" iyz="0.0005" izz="0.1342" />
    </inertial>
    <visual>
      <geometry>
        <mesh filename="../meshes/base_link.STL" />
      </geometry>
      <material name="">
        <color rgba="1 1 1 1" />
      </material>
    </visual>
    <collision>
      <origin xyz="0.16 0 -0.1" />
      <geometry>
        <box size="0.21 0.42 0.55" />
      </geometry>
    </collision>
  </link>
  <link name="Link_waist_yaw">
    <inertial>
      <origin xyz="-0.0042 3.325E-07 0.0490"  />
      <mass value="0.7137" />
      <inertia ixx="0.0010" ixy="-3.4199E-09" ixz="-3.1475E-05" iyy="0.0011" iyz="-2.1109E-09" izz="0.0009" />
    </inertial>
    <visual>
      <geometry>
        <mesh filename="../meshes/Link_waist_yaw.STL" />
      </geometry>
      <material name="">
        <color rgba="1 1 1 1" />
      </material>
    </visual>
  </link>
  <joint name="J_waist_yaw" type="revolute">
    <origin xyz="0.148 0 -0.3356"  />
    <parent link="base_link" />
    <child link="Link_waist_yaw" />
    <axis xyz="0 0 -1" />
    <limit lower="-3.14" upper="3.14" effort="100" velocity="16.8" />
  </joint>
  <link name="Link_waist_roll">
    <inertial>
      <origin xyz="-0.0956 -2.5128E-05 0.0094"  />
      <mass value="2.5956" />
      <inertia ixx="0.0375" ixy="1.7001E-06" ixz="9.5553E-05" iyy="0.0050" iyz="-4.3231E-06" izz="0.0354" />
    </inertial>
    <visual>
      <geometry>
        <mesh filename="../meshes/Link_waist_roll.STL" />
      </geometry>
      <material name="">
        <color rgba="1 1 1 1" />
      </material>
    </visual>
  </link>
  <joint name="J_waist_roll" type="revolute">
    <parent link="Link_waist_yaw" />
    <child link="Link_waist_roll" />
    <axis xyz="0 0 -1" />
    <limit lower="-3.14" upper="3.14" effort="100" velocity="16.8" />
  </joint>
  <link name="Link_hip_r_roll">
    <inertial>
      <origin xyz="0.1348 -3.3250E-07 -0.0055"  />
      <mass value="0.7137" />
      <inertia ixx="0.0010" ixy="3.4199E-09" ixz="3.1475E-05" iyy="0.0011" iyz="-2.1109E-09" izz="0.0009" />
    </inertial>
    <visual>
      <geometry>
        <mesh filename="../meshes/Link_hip_r_roll.STL" />
      </geometry>
      <material name="">
        <color rgba="1 1 1 1" />
      </material>
    </visual>
  </link>
  <joint name="J_hip_r_roll" type="revolute">
    <origin xyz="-0.139 -0.14 -0.0055"  />
    <parent link="Link_waist_roll" />
    <child link="Link_hip_r_roll" />
    <axis xyz="1 0 0" />
    <limit lower="-3.14" upper="3.14" effort="100" velocity="16.8" />
  </joint>
  <link name="Link_hip_r_yaw">
    <inertial>
      <origin xyz="-0.0072 -1.1467E-08 -0.0155"  />
      <mass value="0.1487" />
      <inertia ixx="0.0002" ixy="-1.7351E-11" ixz="-1.4746E-05" iyy="0.0001" iyz="-1.0588E-10" izz="0.0003" />
    </inertial>
    <visual>
      <geometry>
        <mesh filename="../meshes/Link_hip_r_yaw.STL" />
      </geometry>
      <material name="">
        <color rgba="1 1 1 1" />
      </material>
    </visual>
  </link>
  <joint name="J_hip_r_yaw" type="revolute">
    <origin xyz="0.139 0 -0.0553"  />
    <parent link="Link_hip_r_roll" />
    <child link="Link_hip_r_yaw" />
    <axis xyz="0 0 1" />
    <limit lower="-3.14" upper="3.14" effort="100" velocity="16.8" />
  </joint>
  <link name="Link_thigh_r_pitch">
    <inertial>
      <origin xyz="-0.0065 -0.0680 -0.1918"  />
      <mass value="3.0987" />
      <inertia ixx="0.0270" ixy="-7.8982E-07" ixz="0.0035" iyy="0.0401" iyz="2.5703E-06" izz="0.0184" />
    </inertial>
    <visual>
      <geometry>
        <mesh filename="../meshes/Link_thigh_r_pitch.STL" />
      </geometry>
      <material name="">
        <color rgba="1 1 1 1" />
      </material>
    </visual>
  </link>
  <joint name="J_thigh_r_pitch" type="revolute">
    <origin xyz="0 0.0685 -0.0347"  />
    <parent link="Link_hip_r_yaw" />
    <child link="Link_thigh_r_pitch" />
    <axis xyz="0 -1 0" />
    <limit lower="-3.14" upper="3.14" effort="100" velocity="16.8" />
  </joint>
  <link name="Link_shins_r_pitch">
    <inertial>
      <origin xyz="0.0180 -0.0690 -0.1532"  />
      <mass value="1.6314" />
      <inertia ixx="0.0125" ixy="-4.4311E-05" ixz="-0.0006" iyy="0.0129" iyz="5.5400E-05" izz="0.0024" />
    </inertial>
    <visual>
      <geometry>
        <mesh filename="../meshes/Link_shins_r_pitch.STL" />
      </geometry>
      <material name="">
        <color rgba="1 1 1 1" />
      </material>
    </visual>
  </link>
  <joint name="J_shins_r_pitch" type="revolute">
    <origin xyz="0 0 -0.365"  />
    <parent link="Link_thigh_r_pitch" />
    <child link="Link_shins_r_pitch" />
    <axis xyz="0 -1 0" />
    <limit lower="-3.14" upper="3.14" effort="100" velocity="16.8" />
  </joint>
  <link name="Link_backsole_r_pitch">
    <inertial>
      <origin xyz="-1.9134E-12 -0.0250 -0.0090"  />
      <mass value="0.0169" />
      <inertia ixx="3.2280E-06" ixy="1.0473E-16" ixz="2.2819E-16" iyy="3.2279E-06" iyz="4.2924E-16" izz="1.7970E-06" />
    </inertial>
    <visual>
      <geometry>
        <mesh filename="../meshes/Link_backsole_r_pitch.STL" />
      </geometry>
      <material name="">
        <color rgba="1 1 1 1" />
      </material>
    </visual>
  </link>
  <joint name="J_backsole_r_pitch" type="revolute">
    <origin xyz="0 -0.0435 -0.365"  />
    <parent link="Link_shins_r_pitch" />
    <child link="Link_backsole_r_pitch" />
    <axis xyz="0 1 0" />
    <limit lower="-3.14" upper="3.14" effort="100" velocity="16.8" />
  </joint>
  <link name="Link_backsole_roll_r">
    <inertial>
      <origin xyz="-0.0370 9.0269E-06 -0.0375"  />
      <mass value="0.4214" />
      <inertia ixx="0.0004" ixy="-6.1211E-09" ixz="7.9201E-05" iyy="0.0009" iyz="-7.5304E-08" izz="0.0009" />
    </inertial>
    <visual>
      <geometry>
        <mesh filename="../meshes/Link_backsole_r_roll.STL" />
      </geometry>
      <material name="">
        <color rgba="1 1 1 1" />
      </material>
    </visual>
    <collision>
      <origin xyz="-0.006 0.005 -0.047" />
      <geometry>
        <box size="0.29 0.10 0.03" />
      </geometry>
    </collision>
  </link>
  <joint name="J_backsole_r_roll" type="revolute">
    <origin xyz="0.034 -0.025 -0.018"  />
    <parent link="Link_backsole_r_pitch" />
    <child link="Link_backsole_roll_r" />
    <axis xyz="1 0 0" />
    <limit lower="-3.14" upper="3.14" effort="100" velocity="16.8" />
  </joint>
  <link name="Link_frontsole_r_pitch">
    <inertial>
      <origin xyz="0.0369 -0.0278 -0.0121"  />
      <mass value="0.0673" />
      <inertia ixx="4.5322E-05" ixy="-2.1532E-09" ixz="1.6227E-06" iyy="3.0274E-05" iyz="-9.0753E-09" izz="7.2126E-05" />
    </inertial>
    <visual>
      <geometry>
        <mesh filename="../meshes/Link_frontsole_r_pitch.STL" />
      </geometry>
      <material name="">
        <color rgba="1 1 1 1" />
      </material>
    </visual>
  </link>
  <joint name="J_frontsole_r_pitch" type="fixed">
    <origin xyz="0.058 0.0278 -0.0475"  />
    <parent link="Link_backsole_roll_r" />
    <child link="Link_frontsole_r_pitch" />
    <axis xyz="0 -1 0" />
    <limit lower="-3.14" upper="3.14" effort="100" velocity="16.8" />
  </joint>
  <link name="Link_hip_l_roll">
    <inertial>
      <origin xyz="0.1348 -3.3250E-07 -0.0055"  />
      <mass value="0.7137" />
      <inertia ixx="0.0010" ixy="3.4199E-09" ixz="3.1475E-05" iyy="0.0011" iyz="-2.1109E-09" izz="0.0009" />
    </inertial>
    <visual>
      <geometry>
        <mesh filename="../meshes/Link_hip_l_roll.STL" />
      </geometry>
      <material name="">
        <color rgba="1 1 1 1" />
      </material>
    </visual>
  </link>
  <joint name="J_hip_l_roll" type="revolute">
    <origin xyz="-0.139 0.14 -0.0055"  />
    <parent link="Link_waist_roll" />
    <child link="Link_hip_l_roll" />
    <axis xyz="1 0 0" />
    <limit lower="-3.14" upper="3.14" effort="100" velocity="16.8" />
  </joint>
  <link name="Link_hip_l_yaw">
    <inertial>
      <origin xyz="-0.0072 -1.1467E-08 -0.0155"  />
      <mass value="0.1487" />
      <inertia ixx="0.0002" ixy="-1.7351E-11" ixz="-1.4746E-05" iyy="0.0001" iyz="-1.0588E-10" izz="0.0003" />
    </inertial>
    <visual>
      <geometry>
        <mesh filename="../meshes/Link_hip_l_yaw.STL" />
      </geometry>
      <material name="">
        <color rgba="1 1 1 1" />
      </material>
    </visual>
  </link>
  <joint name="J_hip_l_yaw" type="revolute">
    <origin xyz="0.139 0 -0.0553"  />
    <parent link="Link_hip_l_roll" />
    <child link="Link_hip_l_yaw" />
    <axis xyz="0 0 1" />
    <limit lower="-3.14" upper="3.14" effort="100" velocity="16.8" />
  </joint>
  <link name="Link_thigh_l_pitch">
    <inertial>
      <origin xyz="-0.0065 -0.0680 -0.1918"  />
      <mass value="3.0987" />
      <inertia ixx="0.0270" ixy="-6.1575E-07" ixz="0.0035" iyy="0.0401" iyz="1.6242E-06" izz="0.0184" />
    </inertial>
    <visual>
      <geometry>
        <mesh filename="../meshes/Link_thigh_l_pitch.STL" />
      </geometry>
      <material name="">
        <color rgba="1 1 1 1" />
      </material>
    </visual>
  </link>
  <joint name="J_thigh_l_pitch" type="revolute">
    <origin xyz="0 0.0685 -0.0347"  />
    <parent link="Link_hip_l_yaw" />
    <child link="Link_thigh_l_pitch" />
    <axis xyz="0 -1 0" />
    <limit lower="-3.14" upper="3.14" effort="100" velocity="16.8" />
  </joint>
  <link name="Link_shins_l_pitch">
    <inertial>
      <origin xyz="0.0180 -0.0680 -0.1532"  />
      <mass value="1.6314" />
      <inertia ixx="0.0125" ixy="4.6262E-05" ixz="-0.0006" iyy="0.0129" iyz="-5.4292E-05" izz="0.0024" />
    </inertial>
    <visual>
      <geometry>
        <mesh filename="../meshes/Link_shins_l_pitch.STL" />
      </geometry>
      <material name="">
        <color rgba="1 1 1 1" />
      </material>
    </visual>
  </link>
  <joint name="J_shins_l_pitch" type="revolute">
    <origin xyz="0 0 -0.365"  />
    <parent link="Link_thigh_l_pitch" />
    <child link="Link_shins_l_pitch" />
    <axis xyz="0 -1 0" />
    <limit lower="-3.14" upper="3.14" effort="100" velocity="16.8" />
  </joint>
  <link name="Link_backsole_l_pitch">
    <inertial>
      <origin xyz="1.9134E-12 -0.0250 -0.0090"  />
      <mass value="0.0169" />
      <inertia ixx="3.2280E-06" ixy="1.0473E-16" ixz="-2.2819E-16" iyy="3.2279E-06" iyz="-4.2924E-16" izz="1.7970E-06" />
    </inertial>
    <visual>
      <geometry>
        <mesh filename="../meshes/Link_backsole_l_pitch.STL" />
      </geometry>
      <material name="">
        <color rgba="1 1 1 1" />
      </material>
    </visual>
  </link>
  <joint name="J_backsole_l_pitch" type="revolute">
    <origin xyz="0 -0.0435 -0.365"  />
    <parent link="Link_shins_l_pitch" />
    <child link="Link_backsole_l_pitch" />
    <axis xyz="0 1 0" />
    <limit lower="-3.14" upper="3.14" effort="100" velocity="16.8" />
  </joint>
  <link name="Link_backsole_roll_l">
    <inertial>
      <origin xyz="-0.0370 9.0269E-06 -0.0375"  />
      <mass value="0.4214" />
      <inertia ixx="0.0004" ixy="-6.1211E-09" ixz="7.9201E-05" iyy="0.0009" iyz="-7.5304E-08" izz="0.0009" />
    </inertial>
    <visual>
      <geometry>
        <mesh filename="../meshes/Link_backsole_l_roll.STL" />
      </geometry>
      <material name="">
        <color rgba="1 1 1 1" />
      </material>
    </visual>
    <collision>
      <origin xyz="-0.006 0.005 -0.047" />
      <geometry>
        <box size="0.29 0.10 0.03" />
      </geometry>
    </collision>
  </link>
  <joint name="J_backsole_l_roll" type="revolute">
    <origin xyz="0.034 -0.025 -0.018"  />
    <parent link="Link_backsole_l_pitch" />
    <child link="Link_backsole_roll_l" />
    <axis xyz="1 0 0" />
    <limit lower="-3.14" upper="3.14" effort="100" velocity="16.8" />
  </joint>
  <link name="Link_frontsole_l_pitch">
    <inertial>
      <origin xyz="0.0369 -0.0278 -0.0121"  />
      <mass value="0.0673" />
      <inertia ixx="4.5322E-05" ixy="-2.1532E-09" ixz="1.6227E-06" iyy="3.0274E-05" iyz="-9.0753E-09" izz="7.2126E-05" />
    </inertial>
    <visual>
      <geometry>
        <mesh filename="../meshes/Link_frontsole_l_pitch.STL" />
      </geometry>
      <material name="">
        <color rgba="1 1 1 1" />
      </material>
    </visual>
  </link>
  <joint name="J_frontsole_l_pitch" type="fixed">
    <origin xyz="0.058 0.0278 -0.0475"  />
    <parent link="Link_backsole_roll_l" />
    <child link="Link_frontsole_l_pitch" />
    <axis xyz="0 -1 0" />
    <limit lower="-3.14" upper="3.14" effort="100" velocity="16.8" />
  </joint>
</robot>