<?xml version='1.0' encoding='utf-8'?>
<robot name="GR1T2_limbs">
  <link name="base_link">
    <inertial>
      <origin xyz="-0.0603 -9.9E-5 -0.0086"/>
      <mass value="3.96"/>
      <inertia ixx="0.0411" ixy="-6E-6" ixz="-0.0020" iyy="0.0134" iyz="-9E-6" izz="0.0427"/>
    </inertial>
    <visual>
      <geometry>
        <mesh filename="../meshes/base_link.STL"/>
      </geometry>
      <material name="">
        <color rgba="0.7529 0.7529 0.7529 1"/>
      </material>
    </visual>
    <collision name="base_link.STL">
      <origin xyz="-0.0426 0.0004 0.0092" rpy="-1.5716 0.0068 -0.0068"/>
      <geometry>
        <cylinder radius="0.1224" length="0.1371"/>
      </geometry>
    </collision>
  </link>

  <link name="left_thigh_roll_link">
    <inertial>
      <origin xyz="0.0011 2.4e-5 0.0018"/>
      <mass value="1.47"/>
      <inertia ixx="0.0016" ixy="4e-6" ixz="-6e-6" iyy="0.0025" iyz="-9e-6" izz="0.0026"/>
    </inertial>
    <visual>
      <geometry>
        <mesh filename="../meshes/left_thigh_roll_link.STL"/>
      </geometry>
      <material name="">
        <color rgba="0.7529 0.7529 0.7529 1"/>
      </material>
    </visual>
  </link>

  <joint name="left_hip_roll_joint" type="revolute">
    <origin xyz="-0.0316 0.105 -0.0276"/>
    <parent link="base_link"/>
    <child link="left_thigh_roll_link"/>
    <axis xyz="1 0 0"/>
    <limit lower="-0.09" upper="0.79" effort="48" velocity="12.15"/>
  </joint>

  <link name="left_thigh_yaw_link">
    <inertial>
      <origin xyz="-0.0007 0.0384 -0.1103"/>
      <mass value="3.47"/>
      <inertia ixx="0.0200" ixy="-0.0016" ixz="0.0001" iyy="0.0212" iyz="0.0055" izz="0.0115"/>
    </inertial>
    <visual>
      <geometry>
        <mesh filename="../meshes/left_thigh_yaw_link.STL"/>
      </geometry>
      <material name="">
        <color rgba="0.7529 0.7529 0.7529 1"/>
      </material>
    </visual>
  </link>

  <joint name="left_hip_yaw_joint" type="revolute">
    <origin xyz="0.0331 0 0.0008"/>
    <parent link="left_thigh_roll_link"/>
    <child link="left_thigh_yaw_link"/>
    <axis xyz="0 0 1"/>
    <limit lower="-0.7" upper="0.7" effort="66" velocity="16.76"/>
  </joint>

  <link name="left_thigh_pitch_link">
    <inertial>
      <origin xyz="0.0014 -0.0283 -0.0640"/>
      <mass value="8.35"/>
      <inertia ixx="0.0929" ixy="0.0001" ixz="0.0013" iyy="0.0896" iyz="-0.0018" izz="0.0284"/>
    </inertial>
    <visual>
      <geometry>
        <mesh filename="../meshes/left_thigh_pitch_link.STL"/>
      </geometry>
      <material name="">
        <color rgba="0.7529 0.7529 0.7529 1"/>
      </material>
    </visual>
    <collision name="left_thigh_pitch_link.STL">
      <origin xyz="0.0007 -0.030 -0.1671" rpy="0 0 0 "/>
      <geometry>
        <cylinder radius="0.082" length="0.2498"/>
      </geometry>
    </collision>
  </link>

  <joint name="left_hip_pitch_joint" type="revolute">
    <origin xyz="0 0.0223 -0.1403"/>
    <parent link="left_thigh_yaw_link"/>
    <child link="left_thigh_pitch_link"/>
    <axis xyz="0 1 0"/>
    <limit lower="-1.75" upper="0.7" effort="225" velocity="37.38"/>
  </joint>

  <link name="left_shank_pitch_link">
    <inertial>
      <origin xyz="0.0015 -0.0008 -0.1154"/>
      <mass value="1.76"/>
      <inertia ixx="0.0108" ixy="-7e-6" ixz="-0.0001" iyy="0.0107" iyz="-0.0001" izz="0.0013"/>
    </inertial>
    <visual>
      <geometry>
        <mesh filename="../meshes/left_shank_pitch_link.STL"/>
      </geometry>
      <material name="">
        <color rgba="0.7529 0.7529 0.7529 1"/>
      </material>
    </visual>
    <collision name="left_shank_pitch_link.STL">
      <origin xyz="-1.6590e-05 -0.0008 -0.1747" rpy="-3.1411 0.0025 -2.7333"/>
      <geometry>
        <cylinder radius="0.0533" length="0.1808"/>
      </geometry>
    </collision>
  </link>

  <joint name="left_knee_pitch_joint" type="revolute">
    <origin xyz="0 -0.0195 -0.36"/>
    <parent link="left_thigh_pitch_link"/>
    <child link="left_shank_pitch_link"/>
    <axis xyz="0 1 0"/>
    <limit lower="-0.09" upper="1.92" effort="225" velocity="37.38"/>
  </joint>

  <link name="left_foot_pitch_link">
    <inertial>
      <origin xyz="0.0367 0.0003 -0.0364"/>
      <mass value="1.13"/>
      <inertia ixx="0.0009" ixy="1E-6" ixz="0.0003" iyy="0.0052" iyz="-1E-6" izz="0.0056"/>
    </inertial>
    <visual>
      <geometry>
        <mesh filename="../meshes/left_foot_pitch_link.STL"/>
      </geometry>
      <material name="">
        <color rgba="0.7529 0.7529 0.7529 1"/>
      </material>
    </visual>
  </link>

  <joint name="left_ankle_pitch_joint" type="revolute">
    <origin xyz="0 -0.0013 -0.34"/>
    <parent link="left_shank_pitch_link"/>
    <child link="left_foot_pitch_link"/>
    <axis xyz="0 1 0"/>
    <limit lower="-1.05" upper="0.52" effort="15" velocity="20.32"/>
  </joint>

  <link name="left_foot_roll_link">
    <inertial>
      <origin xyz="0.0367 0.0003 -0.0364"/>
      <mass value="1.13"/>
      <inertia ixx="0.0009" ixy="1E-6" ixz="0.0003" iyy="0.0052" iyz="-1E-6" izz="0.0056"/>
    </inertial>
    <visual>
      <geometry>
        <mesh filename="../meshes/left_foot_roll_link.STL"/>
      </geometry>
      <material name="">
        <color rgba="0.7529 0.7529 0.7529 1"/>
      </material>
    </visual>
    <collision name="l_foot_1">
      <origin rpy="0 0 0" xyz="0.05 0.0 -0.035"/>
      <geometry>
        <box size="0.24 0.06 0.02"/>
      </geometry>
    </collision>
<!--    <collision name="l_foot_2">-->
<!--      <origin rpy="0 1.5708 0" xyz="0.05 -0.02 -0.035"/>-->
<!--      <geometry>-->
<!--        <cylinder length="0.24" radius="0.02"/>-->
<!--      </geometry>-->
<!--    </collision>-->
  </link>

  <joint name="left_ankle_roll_joint" type="revolute">
    <parent link="left_foot_pitch_link"/>
    <child link="left_foot_roll_link"/>
    <axis xyz="1 0 0"/>
    <limit lower="-0.44" upper="0.44" effort="30" velocity="20.32"/>
  </joint>

  <link name="right_thigh_roll_link">
    <inertial>
      <origin xyz="0.0013 -9.8e-5 0.0018"/>
      <mass value="1.47"/>
      <inertia ixx="0.0016" ixy="1.2e-5" ixz="-5e-6" iyy="0.0025" iyz="6e-6" izz="0.0026"/>
    </inertial>
    <visual>
      <geometry>
        <mesh filename="../meshes/right_thigh_roll_link.STL"/>
      </geometry>
      <material name="">
        <color rgba="0.7529 0.7529 0.7529 1"/>
      </material>
    </visual>
  </link>

  <joint name="right_hip_roll_joint" type="revolute">
    <origin xyz="-0.0316 -0.105 -0.0276"/>
    <parent link="base_link"/>
    <child link="right_thigh_roll_link"/>
    <axis xyz="1 0 0"/>
    <limit lower="-0.79" upper="0.09" effort="48" velocity="12.15"/>
  </joint>

  <link name="right_thigh_yaw_link">
    <inertial>
      <origin xyz="-0.0007 -0.0384 -0.1104"/>
      <mass value="3.47"/>
      <inertia ixx="0.0191" ixy="-5.8e-5" ixz="0" iyy="0.0212" iyz="-0.0056" izz="0.0115"/>
    </inertial>
    <visual>
      <geometry>
        <mesh filename="../meshes/right_thigh_yaw_link.STL"/>
      </geometry>
      <material name="">
        <color rgba="0.7529 0.7529 0.7529 1"/>
      </material>
    </visual>
  </link>

  <joint name="right_hip_yaw_joint" type="revolute">
    <origin xyz="0.0331 0 0.0008"/>
    <parent link="right_thigh_roll_link"/>
    <child link="right_thigh_yaw_link"/>
    <axis xyz="0 0 1"/>
    <limit lower="-0.7" upper="0.7" effort="66" velocity="16.76"/>
  </joint>

  <link name="right_thigh_pitch_link">
    <inertial>
      <origin xyz="0.0014 0.0282 -0.0640"/>
      <mass value="8.35"/>
      <inertia ixx="0.0931" ixy="9e-5" ixz="0.0015" iyy="0.0896" iyz="-0.0018" izz="0.028"/>
    </inertial>
    <visual>
      <geometry>
        <mesh filename="../meshes/right_thigh_pitch_link.STL"/>
      </geometry>
      <material name="">
        <color rgba="0.7529 0.7529 0.7529 1"/>
      </material>
    </visual>
    <collision name="right_thigh_pitch_link.STL">
      <origin xyz="-0.0021 0.030 -0.1671" rpy="0.0054 0.0141 3.8119e-05"/>
      <geometry>
        <cylinder radius="0.082" length="0.2498"/>
      </geometry>
    </collision>
  </link>

  <joint name="right_hip_pitch_joint" type="revolute">
    <origin xyz="0 -0.0223 -0.1403"/>
    <parent link="right_thigh_yaw_link"/>
    <child link="right_thigh_pitch_link"/>
    <axis xyz="0 1 0"/>
    <limit lower="-1.75" upper="0.7" effort="225" velocity="37.38"/>
  </joint>

  <link name="right_shank_pitch_link">
    <inertial>
      <origin xyz="0.0015 0.0008 -0.1152"/>
      <mass value="1.76"/>
      <inertia ixx="0.0107" ixy="7e-6" ixz="-8.7e-5" iyy="0.0106" iyz="0.0001" izz="0.0012"/>
    </inertial>
    <visual>
      <geometry>
        <mesh filename="../meshes/right_shank_pitch_link.STL"/>
      </geometry>
      <material name="">
        <color rgba="0.7529 0.7529 0.7529 1"/>
      </material>
    </visual>
    <collision name="right_shank_pitch_link.STL">
      <origin xyz="-1.6590e-5 -0.0008 -0.1747"/>
      <geometry>
        <cylinder radius="0.0533" length="0.1808"/>
      </geometry>
    </collision>
  </link>

  <joint name="right_knee_pitch_joint" type="revolute">
    <origin xyz="0 0.0198 -0.36"/>
    <parent link="right_thigh_pitch_link"/>
    <child link="right_shank_pitch_link"/>
    <axis xyz="0 1 0"/>
    <limit lower="-0.09" upper="1.92" effort="225" velocity="37.38"/>
  </joint>

  <link name="right_foot_pitch_link">
    <inertial>
      <origin xyz="0.0370 -0.0003 -0.0364"/>
      <mass value="1.13"/>
      <inertia ixx="0.0009" ixy="-1E-6" ixz="0.0003" iyy="0.0052" iyz="0" izz="0.0057"/>
    </inertial>
    <visual>
      <geometry>
        <mesh filename="../meshes/right_foot_pitch_link.STL"/>
      </geometry>
      <material name="">
        <color rgba="0.7529 0.7529 0.7529 1"/>
      </material>
    </visual>
  </link>

  <joint name="right_ankle_pitch_joint" type="revolute">
    <origin xyz="0 0.0013 -0.34"/>
    <parent link="right_shank_pitch_link"/>
    <child link="right_foot_pitch_link"/>
    <axis xyz="0 1 0"/>
    <limit lower="-1.05" upper="0.52" effort="15" velocity="20.32"/>
  </joint>

  <link name="right_foot_roll_link">
    <inertial>
      <origin xyz="0.0370 -0.0003 -0.0364"/>
      <mass value="1.13"/>
      <inertia ixx="0.0009" ixy="-1E-6" ixz="0.0003" iyy="0.0052" iyz="0" izz="0.0057"/>
    </inertial>
    <visual>
      <geometry>
        <mesh filename="../meshes/right_foot_roll_link.STL"/>
      </geometry>
      <material name="">
        <color rgba="0.7529 0.7529 0.7529 1"/>
      </material>
    </visual>
    <collision name="r_foot_1">
      <origin rpy="0 0 0" xyz="0.05 0.0 -0.035"/>
      <geometry>
        <box size="0.24 0.06 0.02"/>
      </geometry>
    </collision>
<!--    <collision name="r_foot_2">-->
<!--      <origin rpy="0 1.5708 0" xyz="0.05 -0.02 -0.035"/>-->
<!--      <geometry>-->
<!--        <cylinder length="0.24" radius="0.02"/>-->
<!--      </geometry>-->
<!--    </collision>-->
  </link>

  <joint name="right_ankle_roll_joint" type="revolute">
    <parent link="right_foot_pitch_link"/>
    <child link="right_foot_roll_link"/>
    <axis xyz="1 0 0"/>
    <limit lower="-0.44" upper="0.44" effort="30" velocity="20.32"/>
  </joint>

  <link name="waist_yaw_link">
    <inertial>
      <origin xyz="-0.0015 -0.0069 0.0522"/>
      <mass value="1.66"/>
      <inertia ixx="0.0036" ixy="1.476E-05" ixz="5.805E-05" iyy="0.0031" iyz="0.0004" izz="0.0023"/>
    </inertial>
    <visual>
      <geometry>
        <mesh filename="../meshes/waist_yaw_link.STL"/>
      </geometry>
      <material name="">
        <color rgba="0.7529 0.7529 0.7529 1"/>
      </material>
    </visual>
  </link>
  
  <joint name="waist_yaw_joint" type="revolute">
    <parent link="base_link"/>
    <child link="waist_yaw_link"/>
    <axis xyz="0 0 1"/>
    <limit lower="-1.05" upper="1.05" effort="66" velocity="16.76"/>
  </joint>
  <link name="waist_pitch_link">
    <inertial>
      <origin xyz="0.0046 -0.0047 0.0403"/>
      <mass value="1.54"/>
      <inertia ixx="0.0046" ixy="-2.297E-05" ixz="-0.0003" iyy="0.0046" iyz="-0.0002" izz="0.0019"/>
    </inertial>
    <visual>
      <geometry>
        <mesh filename="../meshes/waist_pitch_link.STL"/>
      </geometry>
      <material name="">
        <color rgba="0.7529 0.7529 0.7529 1"/>
      </material>
    </visual>

  </link>
  <joint name="waist_pitch_joint" type="revolute">
    <origin xyz="0 0 0.0869"/>
    <parent link="waist_yaw_link"/>
    <child link="waist_pitch_link"/>
    <axis xyz="0 1 0"/>
    <limit lower="-0.52" upper="1.22" effort="66" velocity="16.76"/>
  </joint>
  <link name="waist_roll_link">
    <inertial>
      <origin xyz="0.0082 0 0.0123"/>
      <mass value="0.96"/>
      <inertia ixx="0.0010" ixy="4.9E-7" ixz="9.99E-5" iyy="1.3098E-3" iyz="-5.3E-7" izz="1.1692E-3"/>
    </inertial>
    <visual>
      <geometry>
        <mesh filename="../meshes/waist_roll_link.STL"/>
      </geometry>
      <material name="">
        <color rgba="0.7529 0.7529 0.7529 1"/>
      </material>
    </visual>

  </link>
  <joint name="waist_roll_joint" type="revolute">
    <origin xyz="0.0053 -0.0005 0.081"/>
    <parent link="waist_pitch_link"/>
    <child link="waist_roll_link"/>
    <axis xyz="1 0 0"/>
    <limit lower="-0.7" upper="0.7" effort="66" velocity="16.76"/>
  </joint>
  <link name="torso_link">
    <inertial>
      <origin xyz="-0.0132 0.0003 0.0095"/>
      <mass value="5.67"/>
      <inertia ixx="0.0408" ixy="-2e-6" ixz="-0.0005" iyy="0.0373" iyz="-1.4e-5" izz="0.0340"/>
    </inertial>
    <visual>
      <geometry>
        <mesh filename="../meshes/torso_link.STL"/>
      </geometry>
      <material name="">
        <color rgba="0.7529 0.7529 0.7529 1"/>
      </material>
    </visual>
    <collision name="torso_link.STL">
      <origin xyz="-0.0158 0.0052 -0.0125"/>
      <geometry>
        <cylinder radius="0.1574" length="0.0604"/>
      </geometry>
    </collision>
  </link>
  
  <joint name="torso_joint" type="fixed">
    <origin xyz="-0.0022 0.0006 0.1603"/>
    <parent link="waist_roll_link"/>
    <child link="torso_link"/>
  </joint>
  
  <link name="left_upper_arm_pitch_link">
    <inertial>
      <origin xyz="0.0033 0.0536 -0.0001"/>
      <mass value="0.82"/>
      <inertia ixx="2.0421E-3" ixy="-1.0845E-4" ixz="-5.7E-6" iyy="5.02E-4" iyz="-2.88E-6" izz="1.9818E-3"/>
    </inertial>
    <visual>
      <geometry>
        <mesh filename="../meshes/left_upper_arm_pitch_link.STL"/>
      </geometry>
      <material name="">
        <color rgba="0.7529 0.7529 0.7529 1"/>
      </material>
    </visual>
  </link>
  
  <joint name="left_shoulder_pitch_joint" type="revolute">
    <origin xyz="0 0.1013 0.0467" rpy="0.4328 0 0"/>
    <parent link="torso_link"/>
    <child link="left_upper_arm_pitch_link"/>
    <axis xyz="0 1 0"/>
    <limit lower="-2.79" upper="1.92" effort="38" velocity="9.11"/>
  </joint>
  
  <link name="left_upper_arm_roll_link">
    <inertial>
      <origin xyz="0.0050 0.0174 -0.0240"/>
      <mass value="0.61"/>
      <inertia ixx="0.0010" ixy="8.5E-07" ixz="-2.686E-05" iyy="0.0008" iyz="0.0003" izz="0.0006"/>
    </inertial>
    <visual>
      <geometry>
        <mesh filename="../meshes/left_upper_arm_roll_link.STL"/>
      </geometry>
      <material name="">
        <color rgba="0.7529 0.7529 0.7529 1"/>
      </material>
    </visual>
  </link>
  
  <joint name="left_shoulder_roll_joint" type="revolute">
    <origin xyz="0 0.0951 0" rpy="-0.4328 0 0"/>
    <parent link="left_upper_arm_pitch_link"/>
    <child link="left_upper_arm_roll_link"/>
    <axis xyz="1 0 0"/>
    <limit lower="-0.57" upper="3.27" effort="38" velocity="9.11"/>
  </joint>
  
  <link name="left_upper_arm_yaw_link">
    <inertial>
      <origin xyz="-1.7E-5 -0.0002 -0.0876"/>
      <mass value="0.54"/>
      <inertia ixx="0.0036" ixy="-1.6E-07" ixz="-7.1E-07" iyy="0.0035" iyz="4.560E-05" izz="0.0003"/>
    </inertial>
    <visual>
      <geometry>
        <mesh filename="../meshes/left_upper_arm_yaw_link.STL"/>
      </geometry>
      <material name="">
        <color rgba="0.7529 0.7529 0.7529 1"/>
      </material>
    </visual>
    <collision name="left_upper_arm_yaw_link.STL">
      <origin xyz="3.9485e-05 -0.0009 -0.0793" rpy="-3.1256 0.0015 -0.1885"/>
      <geometry>
        <cylinder radius="0.0362" length="0.1699"/>
      </geometry>
    </collision>
  </link>
  
  <joint name="left_shoulder_yaw_joint" type="revolute">
    <origin xyz="0 0.04 -0.0709"/>
    <parent link="left_upper_arm_roll_link"/>
    <child link="left_upper_arm_yaw_link"/>
    <axis xyz="0 0 1"/>
    <limit lower="-2.97" upper="2.97" effort="30" velocity="7.33"/>
  </joint>
  
  <link name="left_lower_arm_pitch_link">
    <inertial>
      <origin xyz="0 0.0081 -0.0253"/>
      <mass value="0.33"/>
      <inertia ixx="0.0003" ixy="2E-08" ixz="7E-08" iyy="0.0003" iyz="-5.014E-05" izz="0.0001"/>
    </inertial>
    <visual>
      <geometry>
        <mesh filename="../meshes/left_lower_arm_pitch_link.STL"/>
      </geometry>
      <material name="">
        <color rgba="0.7529 0.7529 0.7529 1"/>
      </material>
    </visual>
  </link>
  
  <joint name="left_elbow_pitch_joint" type="revolute">
    <origin xyz="0 0.0011 -0.1786"/>
    <parent link="left_upper_arm_yaw_link"/>
    <child link="left_lower_arm_pitch_link"/>
    <axis xyz="0 1 0"/>
    <limit lower="-2.27" upper="2.27" effort="30" velocity="7.33"/>
  </joint>
  
  <link name="left_hand_yaw_link">
    <inertial>
      <origin xyz="0.0004 0.0020 -0.0731"/>
      <mass value="0.99"/>
      <inertia ixx="0.0026" ixy="1.29E-06" ixz="6.12E-06" iyy="0.0025" iyz="-1.585E-05" izz="0.0005"/>
    </inertial>
    <visual>
      <geometry>
        <mesh filename="../meshes/left_hand_yaw_link.STL"/>
      </geometry>
      <material name="">
        <color rgba="0.7529 0.7529 0.7529 1"/>
      </material>
    </visual>
    <collision name="left_hand_yaw_link.STL">
      <origin xyz="0.0011 -0.0015 -0.0760"/>
      <geometry>
        <cylinder radius="0.0416" length="0.1392"/>
      </geometry>
    </collision>
  </link>
  
  <joint name="left_wrist_yaw_joint" type="revolute">
    <origin xyz="0 0 -0.0595"/>
    <parent link="left_lower_arm_pitch_link"/>
    <child link="left_hand_yaw_link"/>
    <axis xyz="0 0 1"/>
    <limit lower="-2.97" upper="2.97" effort="10.2" velocity="24.4"/>
  </joint>
  
  <link name="left_hand_roll_link">
    <inertial>
      <origin xyz="0 0.0051 -0.0085"/>
      <mass value="0.055"/>
      <inertia ixx="1.1E-5" ixy="0" ixz="0" iyy="2E-5" iyz="-1E-6" izz="2.1E-5"/>
    </inertial>
    <visual>
      <geometry>
        <mesh filename="../meshes/left_hand_roll_link.STL"/>
      </geometry>
      <material name="">
        <color rgba="0.7529 0.7529 0.7529 1"/>
      </material>
    </visual>
  </link>
  
  <joint name="left_wrist_roll_joint" type="revolute">
    <origin xyz="0 0 -0.1911"/>
    <parent link="left_hand_yaw_link"/>
    <child link="left_hand_roll_link"/>
    <axis xyz="1 0 0"/>
    <limit lower="-0.61" upper="0.61" effort="3.95" velocity="27.96"/>
  </joint>
  
  <link name="left_hand_pitch_link">
    <inertial>
      <origin xyz="0 0.0051 -0.0085"/>
      <mass value="0.055"/>
      <inertia ixx="1.1E-5" ixy="0" ixz="0" iyy="2E-5" iyz="-1E-6" izz="2.1E-5"/>
    </inertial>
    <visual>
      <geometry>
        <mesh filename="../meshes/left_hand_pitch_link.STL"/>
      </geometry>
      <material name="">
        <color rgba="0.7529 0.7529 0.7529 1"/>
      </material>
    </visual>
  </link>

  <joint name="left_wrist_pitch_joint" type="revolute">
    <parent link="left_hand_roll_link"/>
    <child link="left_hand_pitch_link"/>
    <axis xyz="0 1 0"/>
    <limit lower="-0.96" upper="0.87" effort="3.95" velocity="27.96"/>
  </joint>

  <joint name="L_base_link_joint" type="fixed">
    <origin xyz="0 0 -0.022"/>
    <parent link="left_wrist_pitch_link"/>
    <child link="L_hand_base_link"/>
  </joint>

  <link name="L_hand_base_link">
    <inertial>
      <origin xyz="-0.0026 -0.0660 -0.0019"/>
      <mass value="0.1414"/>
      <inertia ixx="0.0001" ixy="2.1995E-06" ixz="-1.7694E-06" iyy="8.3835E-05" iyz="1.5968E-06" izz="7.7231E-05"/>
    </inertial>
    <visual>
      <origin  rpy="1.5708 0 1.5708"/>
      <geometry>
        <mesh filename="../meshes/inspire_hand/base_link_l.STL"/>
      </geometry>
      <material name="">
        <color rgba="1 1 1 1"/>
      </material>
    </visual>
  </link>

  <link name="L_thumb_proximal_base">
    <inertial>
      <origin xyz="-0.0049 0.0004 -0.0072"/>
      <mass value="0.0019"/>
      <inertia ixx="5.5158E-08" ixy="-1.1803E-08" ixz="-4.6743E-09" iyy="8.2164E-08" iyz="-1.3521E-09" izz="6.7434E-08"/>
    </inertial>
    <visual>
      <geometry>
        <mesh filename="../meshes/inspire_hand/Link11_l.STL"/>
      </geometry>
      <material name="">
        <color rgba="0.8275 0.8392 0.8275 1"/>
      </material>
    </visual>
  </link>

  <joint name="L_thumb_proximal_yaw_joint" type="fixed">
    <origin xyz="0.0204 -0.0170 -0.0691" rpy="3.14 0 0"/>
    <parent link="L_hand_base_link"/>
    <child link="L_thumb_proximal_base"/>
    <axis xyz="0 0 1"/>
    <limit lower="-0.1" upper="1.3" effort="1" velocity="0.5"/>
  </joint>

  <link name="L_thumb_proximal">
    <inertial>
      <origin xyz="0.0219 -0.0128 -0.0080"/>
      <mass value="0.0066"/>
      <inertia ixx="1.5693E-06" ixy="7.8339E-07" ixz="8.5959E-10" iyy="1.7356E-06" iyz="1.0378E-09" izz="2.787E-06"/>
    </inertial>
    <visual>
      <geometry>
        <mesh filename="../meshes/inspire_hand/Link12_l.STL"/>
      </geometry>
      <material name="">
        <color rgba="1 1 1 1"/>
      </material>
    </visual>
  </link>

  <joint name="L_thumb_proximal_pitch_joint" type="fixed">
    <origin xyz="0.0100 0.0098 -0.0089" rpy="-1.5708 0 0.1694"/>
    <parent link="L_thumb_proximal_base"/>
    <child link="L_thumb_proximal"/>
    <axis xyz="0 0 -1"/>
    <limit lower="-0.1" upper="0.6" effort="1" velocity="0.5"/>
  </joint>

  <link name="L_thumb_intermediate">
    <inertial>
      <origin xyz="0.0096 0.0016 -0.0072"/>
      <mass value="0.0038"/>
      <inertia ixx="3.6981E-07" ixy="9.8603E-08" ixz="-2.8173E-12" iyy="3.2395E-07" iyz="-2.8028E-12" izz="4.6532E-07"/>
    </inertial>
    <visual>
      <geometry>
        <mesh filename="../meshes/inspire_hand/Link13_l.STL"/>
      </geometry>
      <material name="">
        <color rgba="1 1 1 1"/>
      </material>
    </visual>
  </link>

  <joint name="L_thumb_intermediate_joint" type="fixed">
    <origin xyz="0.0441 -0.0346 -0.0008"/>
    <parent link="L_thumb_proximal"/>
    <child link="L_thumb_intermediate"/>
    <axis xyz="0 0 -1"/>
    <limit lower="0" upper="0.8" effort="1" velocity="0.5"/>
    <mimic joint="L_thumb_proximal_pitch_joint" multiplier="1.6" offset="0"/>
  </joint>

  <link name="L_thumb_distal">
    <inertial>
      <origin xyz="0.0093 -0.0050 -0.0060"/>
      <mass value="0.0033"/>
      <inertia ixx="1.3632E-07" ixy="5.6787E-08" ixz="-9.1939E-11" iyy="1.4052E-07" iyz="1.2145E-10" izz="2.0026E-07"/>
    </inertial>
    <visual>
      <geometry>
        <mesh filename="../meshes/inspire_hand/Link14_l.STL"/>
      </geometry>
      <material name="">
        <color rgba="1 1 1 1"/>
      </material>
    </visual>
  </link>

  <joint name="L_thumb_distal_joint" type="fixed">
    <origin xyz="0.0202 -0.0102 -0.0012"/>
    <parent link="L_thumb_intermediate"/>
    <child link="L_thumb_distal"/>
    <axis xyz="0 0 -1"/>
    <limit lower="0" upper="1.2" effort="1" velocity="0.5"/>
    <mimic joint="L_thumb_proximal_pitch_joint" multiplier="2.4" offset="0"/>
  </joint>


  <link name="L_thumb_tip">
    <inertial>
      <origin xyz="0 0 0"/>
      <mass value="0.006"/>
      <inertia ixx="1E-8" ixy="1E-12" ixz="1E-12" iyy="1E-8" iyz="1E-12" izz="1E-8"/>
    </inertial>
    <visual>
      <geometry>
        <sphere radius="0.005"/>
      </geometry>
      <material name="green">
        <color rgba="0 1 0 1"/>
      </material>
    </visual>
  </link>
  <joint name="L_thumb_tip_joint" type="fixed">
    <parent link="L_thumb_distal"/>
    <child link="L_thumb_tip"/>
    <origin  xyz="0.015 -0.013 -0.004"/>
  </joint>


  <link name="L_index_proximal">
    <inertial>
      <origin xyz="0.0013 -0.0119 -0.0060"/>
      <mass value="0.0042"/>
      <inertia ixx="6.6215E-07" ixy="1.8442E-08" ixz="1.3746E-12" iyy="2.1167E-07" iyz="-1.4773E-11" izz="6.9402E-07"/>
    </inertial>
    <visual>
      <geometry>
        <mesh filename="../meshes/inspire_hand/Link15_l.STL"/>
      </geometry>
      <material name="">
        <color rgba="0.7922 0.8196 0.9333 1"/>
      </material>
    </visual>
  </link>

  <joint name="L_index_proximal_joint" type="fixed">
    <origin xyz="0.0323 0.0003 -0.1365" rpy="1.5708 -0.0349 1.5708"/>
    <parent link="L_hand_base_link"/>
    <child link="L_index_proximal"/>
    <axis xyz="0 0 -1"/>
    <limit lower="0" upper="1.7" effort="1" velocity="0.5"/>
  </joint>

  <link name="L_index_intermediate">
    <inertial>
      <origin xyz="0.0022 -0.0196 -0.005"/>
      <mass value="0.0046"/>
      <inertia ixx="7.6284E-07" ixy="-8.063E-08" ixz="3.6797E-13" iyy="9.4308E-08" iyz="1.5743E-13" izz="7.8176E-07"/>
    </inertial>
    <visual>
      <geometry>
        <mesh filename="../meshes/inspire_hand/Link16_l.STL"/>
      </geometry>
      <material name="">
        <color rgba="1 1 1 1"/>
      </material>
    </visual>
  </link>

  <joint name="L_index_intermediate_joint" type="fixed">
    <origin xyz="-0.0024 -0.0320 -0.001"/>
    <parent link="L_index_proximal"/>
    <child link="L_index_intermediate"/>
    <axis xyz="0 0 -1"/>
    <limit lower="0" upper="1.7" effort="1" velocity="0.5"/>
    <mimic joint="L_index_proximal_joint" multiplier="1" offset="0"/>
  </joint>



  <link name="L_index_tip">
    <inertial>
      <origin xyz="0 0 0"/>
      <mass value="0.006"/>
      <inertia ixx="1E-8" ixy="1E-12" ixz="1E-12" iyy="1E-8" iyz="1E-12" izz="1E-8"/>
    </inertial>
    <visual>
      <geometry>
        <sphere radius="0.005"/>
      </geometry>
      <material name="green">
        <color rgba="0 1 0 1"/>
      </material>
    </visual>
  </link>

  <joint name="L_index_tip_joint" type="fixed">
    <parent link="L_index_intermediate"/>
    <child link="L_index_tip"/>
    <origin  xyz="-0.005 -0.04 -0.004"/>
  </joint>

  <link name="L_middle_proximal">
    <inertial>
      <origin xyz="0.0013 -0.0119 -0.0060"/>
      <mass value="0.0042"/>
      <inertia ixx="6.6215E-07" ixy="1.8442E-08" ixz="1.2299E-12" iyy="2.1167E-07" iyz="-1.4484E-11" izz="6.9402E-07"/>
    </inertial>
    <visual>
      <geometry>
        <mesh filename="../meshes/inspire_hand/Link17_l.STL"/>
      </geometry>
      <material name="">
        <color rgba="0.7922 0.8196 0.9333 1"/>
      </material>
    </visual>
  </link>

  <joint name="L_middle_proximal_joint" type="fixed">
    <origin xyz="0.0129 0.0003 -0.1371" rpy="1.5708 0 1.5708"/>
    <parent link="L_hand_base_link"/>
    <child link="L_middle_proximal"/>
    <axis xyz="0 0 -1"/>
    <limit lower="0" upper="1.7" effort="1" velocity="0.5"/>
  </joint>

  <link name="L_middle_intermediate">
    <inertial>
      <origin xyz="0.0019 -0.0208 -0.0050"/>
      <mass value="0.0050"/>
      <inertia ixx="9.5823E-07" ixy="-1.1425E-07" ixz="-2.4186E-12" iyy="1.0646E-07" iyz="3.6974E-12" izz="9.8385E-07"/>
    </inertial>
    <visual>
      <geometry>
        <mesh filename="../meshes/inspire_hand/Link18_l.STL"/>
      </geometry>
      <material name="">
        <color rgba="0.8275 0.8392 0.8275 1"/>
      </material>
    </visual>
  </link>

  <joint name="L_middle_intermediate_joint" type="fixed">
    <origin xyz="-0.0024 -0.0320 -0.001"/>
    <parent link="L_middle_proximal"/>
    <child link="L_middle_intermediate"/>
    <axis xyz="0 0 -1"/>
    <limit lower="0" upper="1.7" effort="1" velocity="0.5"/>
    <mimic joint="L_middle_proximal_joint" multiplier="1" offset="0"/>
  </joint>

  <link name="L_middle_tip">
    <inertial>
      <origin xyz="0 0 0"/>
      <mass value="0.006"/>
      <inertia ixx="1E-8" ixy="1E-12" ixz="1E-12" iyy="1E-8" iyz="1E-12" izz="1E-8"/>
    </inertial>
    <visual>
      <geometry>
        <sphere radius="0.005"/>
      </geometry>
      <material name="green">
        <color rgba="0 1 0 1"/>
      </material>
    </visual>
  </link>

  <joint name="L_middle_tip_joint" type="fixed">
    <parent link="L_middle_intermediate"/>
    <child link="L_middle_tip"/>
    <origin  xyz="-0.005 -0.045 -0.004"/>
  </joint>

  <link name="L_ring_proximal">
    <inertial>
      <origin xyz="0.0013 -0.0119 -0.0060"/>
      <mass value="0.0042"/>
      <inertia ixx="6.6215E-07" ixy="1.8442E-08" ixz="9.6052E-13" iyy="2.1167E-07" iyz="-1.4124E-11" izz="6.9402E-07"/>
    </inertial>
    <visual>
      <geometry>
        <mesh filename="../meshes/inspire_hand/Link19_l.STL"/>
      </geometry>
      <material name="">
        <color rgba="0.7922 0.8196 0.9333 1"/>
      </material>
    </visual>
  </link>

  <joint name="L_ring_proximal_joint" type="fixed">
    <origin xyz="-0.0063 0.0003 -0.1369" rpy="1.5708 0.0524 1.5708"/>
    <parent link="L_hand_base_link"/>
    <child link="L_ring_proximal"/>
    <axis xyz="0 0 -1"/>
    <limit lower="0" upper="1.7" effort="1" velocity="0.5"/>
  </joint>

  <link name="L_ring_intermediate">
    <inertial>
      <origin xyz="0.0022 -0.0196 -0.005"/>
      <mass value="0.0046"/>
      <inertia ixx="7.6285E-07" ixy="-8.0631E-08" ixz="3.3472E-14" iyy="9.4308E-08" iyz="-4.4773E-13" izz="7.8176E-07"/>
    </inertial>
    <visual>
      <geometry>
        <mesh filename="../meshes/inspire_hand/Link20_l.STL"/>
      </geometry>
      <material name="">
        <color rgba="1 1 1 1"/>
      </material>
    </visual>
  </link>

  <joint name="L_ring_intermediate_joint" type="fixed">
    <origin xyz="-0.0024 -0.0320 -0.001"/>
    <parent link="L_ring_proximal"/>
    <child link="L_ring_intermediate"/>
    <axis xyz="0 0 -1"/>
    <limit lower="0" upper="1.7" effort="1" velocity="0.5"/>
    <mimic joint="L_ring_proximal_joint" multiplier="1" offset="0"/>
  </joint>

  <link name="L_ring_tip">
    <inertial>
      <origin xyz="0 0 0"/>
      <mass value="0.006"/>
      <inertia ixx="1E-8" ixy="1E-12" ixz="1E-12" iyy="1E-8" iyz="1E-12" izz="1E-8"/>
    </inertial>
    <visual>
      <geometry>
        <sphere radius="0.005"/>
      </geometry>
      <material name="green">
        <color rgba="0 1 0 1"/>
      </material>
    </visual>
  </link>

  <joint name="L_ring_tip_joint" type="fixed">
    <parent link="L_ring_intermediate"/>
    <child link="L_ring_tip"/>
    <origin  xyz="-0.002 -0.04 -0.004"/>
  </joint>

  <link name="L_pinky_proximal">
    <inertial>
      <origin xyz="0.0013 -0.0119 -0.0060"/>
      <mass value="0.0042"/>
      <inertia ixx="6.6215E-07" ixy="1.8442E-08" ixz="1.0279E-12" iyy="2.1167E-07" iyz="-1.4277E-11" izz="6.9402E-07"/>
    </inertial>
    <visual>
      <geometry>
        <mesh filename="../meshes/inspire_hand/Link21_l.STL"/>
      </geometry>
      <material name="">
        <color rgba="0.7922 0.8196 0.9333 1"/>
      </material>
    </visual>
  </link>

  <joint name="L_pinky_proximal_joint" type="fixed">
    <origin xyz="-0.0255 0.0003 -0.1357" rpy="1.5708 0.1047 1.5708"/>
    <parent link="L_hand_base_link"/>
    <child link="L_pinky_proximal"/>
    <axis xyz="0 0 -1"/>
    <limit lower="0" upper="1.7" effort="1" velocity="0.5"/>
  </joint>

  <link name="L_pinky_intermediate">
    <inertial>
      <origin xyz="0.0025 -0.0162 -0.0050"/>
      <mass value="0.0036"/>
      <inertia ixx="4.3923E-07" ixy="-4.1355E-08" ixz="1.2263E-12" iyy="7.0315E-08" iyz="3.1311E-12" izz="4.4881E-07"/>
    </inertial>
    <visual>
      <geometry>
        <mesh filename="../meshes/inspire_hand/Link22_l.STL"/>
      </geometry>
      <material name="">
        <color rgba="1 1 1 1"/>
      </material>
    </visual>
  </link>

  <joint name="L_pinky_intermediate_joint" type="fixed">
    <origin xyz="-0.0024 -0.0320 -0.001"/>
    <parent link="L_pinky_proximal"/>
    <child link="L_pinky_intermediate"/>
    <axis xyz="0 0 -1"/>
    <limit lower="0" upper="1.7" effort="1" velocity="0.5"/>
    <mimic joint="L_pinky_proximal_joint" multiplier="1" offset="0"/>
  </joint>


  <link name="L_pinky_tip">
    <inertial>
      <origin xyz="0 0 0"/>
      <mass value="0.006"/>
      <inertia ixx="1E-8" ixy="1E-12" ixz="1E-12" iyy="1E-8" iyz="1E-12" izz="1E-8"/>
    </inertial>
    <visual>
      <geometry>
        <sphere radius="0.005"/>
      </geometry>
      <material name="green">
        <color rgba="0 1 0 1"/>
      </material>
    </visual>
  </link>

  <joint name="L_pinky_tip_joint" type="fixed">
    <parent link="L_pinky_intermediate"/>
    <child link="L_pinky_tip"/>
    <origin  xyz="-0.002 -0.032 -0.004"/>
  </joint>
  
  <link name="right_upper_arm_pitch_link">
    <inertial>
      <origin xyz="0.0034 -0.0536 0.0002"/>
      <mass value="0.82"/>
      <inertia ixx="0.0020" ixy="0.0001" ixz="-3.5E-07" iyy="0.0005" iyz="-3.27E-06" izz="0.0020"/>
    </inertial>
    <visual>
      <geometry>
        <mesh filename="../meshes/right_upper_arm_pitch_link.STL"/>
      </geometry>
      <material name="">
        <color rgba="0.7529 0.7529 0.7529 1"/>
      </material>
    </visual>
  </link>

  <joint name="right_shoulder_pitch_joint" type="revolute">
    <origin xyz="0 -0.1013 0.0467" rpy="-0.4328 0 0"/>
    <parent link="torso_link"/>
    <child link="right_upper_arm_pitch_link"/>
    <axis xyz="0 1 0"/>
    <limit lower="-2.79" upper="1.92" effort="38" velocity="9.11"/>
  </joint>
  
  <link name="right_upper_arm_roll_link">
    <inertial>
      <origin xyz="0.0045 -0.0174 -0.0240"/>
      <mass value="0.61"/>
      <inertia ixx="0.0010" ixy="-8.4E-07" ixz="-2.687E-05" iyy="0.0008" iyz="-0.0003" izz="0.0006"/>
    </inertial>
    <visual>
      <geometry>
        <mesh filename="../meshes/right_upper_arm_roll_link.STL"/>
      </geometry>
      <material name="">
        <color rgba="0.7529 0.7529 0.7529 1"/>
      </material>
    </visual>
  </link>

  <joint name="right_shoulder_roll_joint" type="revolute">
    <origin xyz="0 -0.0951 0" rpy="0.4328 0 0"/>
    <parent link="right_upper_arm_pitch_link"/>
    <child link="right_upper_arm_roll_link"/>
    <axis xyz="1 0 0"/>
    <limit lower="-3.27" upper="0.57" effort="38" velocity="9.11"/>
  </joint>
  
  <link name="right_upper_arm_yaw_link">
    <inertial>
      <origin xyz="-1E-5 0.0002 -0.0876"/>
      <mass value="0.54"/>
      <inertia ixx="0.0036" ixy="3E-08" ixz="7E-08" iyy="0.0035" iyz="-4.555E-05" izz="0.0003"/>
    </inertial>
    <visual>
      <geometry>
        <mesh filename="../meshes/right_upper_arm_yaw_link.STL"/>
      </geometry>
      <material name="">
        <color rgba="0.7529 0.7529 0.7529 1"/>
      </material>
    </visual>
    <collision name="right_upper_arm_yaw_link.STL">
      <origin xyz="3.9485e-05 0.0009 -0.0793"/>
      <geometry>
        <cylinder radius="0.0362" length="0.1699"/>
      </geometry>
    </collision>
  </link>
  
  <joint name="right_shoulder_yaw_joint" type="revolute">
    <origin xyz="0 -0.04 -0.0709"/>
    <parent link="right_upper_arm_roll_link"/>
    <child link="right_upper_arm_yaw_link"/>
    <axis xyz="0 0 1"/>
    <limit lower="-2.97" upper="2.97" effort="30" velocity="7.33"/>
  </joint>
  
  <link name="right_lower_arm_pitch_link">
    <inertial>
      <origin xyz="0 -0.0081 -0.0253"/>
      <mass value="0.33"/>
      <inertia ixx="0.0003" ixy="2E-08" ixz="-7E-08" iyy="0.0003" iyz="5.014E-05" izz="0.0001"/>
    </inertial>
    <visual>
      <geometry>
        <mesh filename="../meshes/right_lower_arm_pitch_link.STL"/>
      </geometry>
      <material name="">
        <color rgba="0.7529 0.7529 0.7529 1"/>
      </material>
    </visual>
  </link>

  <joint name="right_elbow_pitch_joint" type="revolute">
    <origin xyz="0 -0.0011 -0.1786"/>
    <parent link="right_upper_arm_yaw_link"/>
    <child link="right_lower_arm_pitch_link"/>
    <axis xyz="0 1 0"/>
    <limit lower="-2.27" upper="2.27" effort="30" velocity="7.33"/>
  </joint>
  
  <link name="right_hand_yaw_link">
    <inertial>
      <origin xyz="0.0005 -0.0020 -0.0724"/>
      <mass value="0.99"/>
      <inertia ixx="0.0026" ixy="3.47E-06" ixz="2.86E-06" iyy="0.0025" iyz="1.62E-05" izz="0.0005"/>
    </inertial>
    <visual>
      <geometry>
        <mesh filename="../meshes/right_hand_yaw_link.STL"/>
      </geometry>
      <material name="">
        <color rgba="0.7529 0.7529 0.7529 1"/>
      </material>
    </visual>
    <collision name="right_hand_yaw_link.STL">
      <origin xyz="0.0011 0.0006 -0.0760"/>
      <geometry>
        <cylinder radius="0.0416" length="0.1392"/>
      </geometry>
    </collision>
  </link>
  
  <joint name="right_wrist_yaw_joint" type="revolute">
    <origin xyz="0 0 -0.0595"/>
    <parent link="right_lower_arm_pitch_link"/>
    <child link="right_hand_yaw_link"/>
    <axis xyz="0 0 1"/>
    <limit lower="-2.97" upper="2.97" effort="10.2" velocity="24.4"/>
  </joint>
  <link name="right_hand_roll_link">
    <inertial>
      <origin xyz="0 0.0051 -0.0085"/>
      <mass value="0.055"/>
      <inertia ixx="1.1E-5" ixy="0" ixz="0" iyy="2E-5" iyz="-1E-6" izz="2.1E-5"/>
    </inertial>
    <visual>
      <geometry>
        <mesh filename="../meshes/right_hand_roll_link.STL"/>
      </geometry>
      <material name="">
        <color rgba="0.7529 0.7529 0.7529 1"/>
      </material>
    </visual>
  </link>

  <joint name="right_wrist_roll_joint" type="revolute">
    <origin xyz="0 0 -0.1911"/>
    <parent link="right_hand_yaw_link"/>
    <child link="right_hand_roll_link"/>
    <axis xyz="1 0 0"/>
    <limit lower="-0.61" upper="0.61" effort="3.95" velocity="27.96"/>
  </joint>
  
  <link name="right_hand_pitch_link">
    <inertial>
      <origin xyz="0 0.0051 -0.0085"/>
      <mass value="0.055"/>
      <inertia ixx="1.1E-5" ixy="0" ixz="0" iyy="2E-5" iyz="-1E-6" izz="2.1E-5"/>
    </inertial>
    <visual>
      <geometry>
        <mesh filename="../meshes/right_hand_pitch_link.STL"/>
      </geometry>
      <material name="">
        <color rgba="0.7529 0.7529 0.7529 1"/>
      </material>
    </visual>
  </link>

  <joint name="right_wrist_pitch_joint" type="revolute">
    <parent link="right_hand_roll_link"/>
    <child link="right_hand_pitch_link"/>
    <axis xyz="0 1 0"/>
    <limit lower="-0.96" upper="0.87" effort="3.95" velocity="27.96"/>
  </joint>

  <joint name="R_base_link_joint" type="fixed">
    <origin xyz="0 0 -0.022"/>
    <parent link="right_hand_pitch_link"/>
    <child link="R_hand_base_link"/>
  </joint>

  <link name="R_hand_base_link">
    <inertial>
      <origin xyz="-0.0025 -0.0660 0.0020"/>
      <mass value="0.1414"/>
      <inertia ixx="0.0001" ixy="2.1711E-06" ixz="1.7709E-06" iyy="8.3832E-05" iyz="-1.6551E-06" izz="7.6663E-05"/>
    </inertial>
    <visual>
      <origin rpy="1.5708 0 -1.5708"/>
      <geometry>
        <mesh filename="../meshes/inspire_hand/base_link_r.STL"/>
      </geometry>
      <material name="">
        <color rgba="1 1 1 1"/>
      </material>
    </visual>
  </link>

  <link name="R_thumb_proximal_base">
    <inertial>
      <origin xyz="-0.0048 0.0009 -0.0076"/>
      <mass value="0.0019"/>
      <inertia ixx="5.816E-08" ixy="1.4539E-08" ixz="4.491E-09" iyy="7.9161E-08" iyz="-1.8727E-09" izz="6.7433E-08"/>
    </inertial>
    <visual>
      <geometry>
        <mesh filename="../meshes/inspire_hand/Link11_r.STL"/>
      </geometry>
      <material name="">
        <color rgba="1 1 1 1"/>
      </material>
    </visual>
  </link>

  <joint name="R_thumb_proximal_yaw_joint" type="fixed">
    <origin xyz="0.0204 0.0170 -0.0691" rpy="0 3.1416 0"/>
    <parent link="R_hand_base_link"/>
    <child link="R_thumb_proximal_base"/>
    <axis xyz="0 0 -1"/>
    <limit lower="-0.1" upper="1.3" effort="1" velocity="0.5"/>
  </joint>

  <link name="R_thumb_proximal">
    <inertial>
      <origin xyz="0.0219 0.0128 -0.0080"/>
      <mass value="0.0066"/>
      <inertia ixx="1.5686E-06" ixy="-7.8296E-07" ixz="8.9143E-10" iyy="1.7353E-06" iyz="-1.0191E-09" izz="2.786E-06"/>
    </inertial>
    <visual>
      <geometry>
        <mesh filename="../meshes/inspire_hand/Link12_r.STL"/>
      </geometry>
      <material name="">
        <color rgba="1 1 1 1"/>
      </material>
    </visual>
  </link>

  <joint name="R_thumb_proximal_pitch_joint" type="fixed">
    <origin xyz="-0.0088 0.0109 -0.0092" rpy="1.5708 0 2.8587"/>
    <parent link="R_thumb_proximal_base"/>
    <child link="R_thumb_proximal"/>
    <axis xyz="0 0 1"/>
    <limit lower="-0.1" upper="0.6" effort="1" velocity="0.5"/>
  </joint>

  <link name="R_thumb_intermediate">
    <inertial>
      <origin xyz="0.0096 -0.0016 -0.0072"/>
      <mass value="0.0038"/>
      <inertia ixx="3.6981E-07" ixy="-9.8581E-08" ixz="-4.7469E-12" iyy="3.2394E-07" iyz="1.0939E-12" izz="4.6531E-07"/>
    </inertial>
    <visual>
      <geometry>
        <mesh filename="../meshes/inspire_hand/Link13_r.STL"/>
      </geometry>
      <material name="">
        <color rgba="1 1 1 1"/>
      </material>
    </visual>
  </link>

  <joint name="R_thumb_intermediate_joint" type="fixed">
    <origin xyz="0.0441 0.0346 -0.0008"/>
    <parent link="R_thumb_proximal"/>
    <child link="R_thumb_intermediate"/>
    <axis xyz="0 0 1"/>
    <limit lower="0" upper="0.8" effort="1" velocity="0.5"/>
    <mimic joint="R_thumb_proximal_pitch_joint" multiplier="1.6" offset="0"/>
  </joint>

  <link name="R_thumb_distal">
    <inertial>
      <origin xyz="0.0093 0.0050 -0.0060"/>
      <mass value="0.0033"/>
      <inertia ixx="1.3632E-07" ixy="-5.6788E-08" ixz="-9.2764E-11" iyy="1.4052E-07" iyz="-1.2283E-10" izz="2.0026E-07"/>
    </inertial>
    <visual>
      <geometry>
        <mesh filename="../meshes/inspire_hand/Link14_r.STL"/>
      </geometry>
      <material name="">
        <color rgba="1 1 1 1"/>
      </material>
    </visual>
  </link>

  <joint name="R_thumb_distal_joint" type="fixed">
    <origin xyz="0.0202 0.0102 -0.0012"/>
    <parent link="R_thumb_intermediate"/>
    <child link="R_thumb_distal"/>
    <axis xyz="0 0 1"/>
    <limit lower="0" upper="1.2" effort="1" velocity="0.5"/>
    <mimic joint="R_thumb_proximal_pitch_joint" multiplier="2.4" offset="0"/>
  </joint>

  <link name="R_thumb_tip">
    <inertial>
      <origin xyz="0 0 0"/>
      <mass value="0.006"/>
      <inertia ixx="1E-8" ixy="1E-12" ixz="1E-12" iyy="1E-8" iyz="1E-12" izz="1E-8"/>
    </inertial>
    <visual>
      <geometry>
        <sphere radius="0.005"/>
      </geometry>
      <material name="green">
        <color rgba="0 1 0 1"/>
      </material>
    </visual>
  </link>

  <joint name="R_thumb_tip_joint" type="fixed">
    <parent link="R_thumb_distal"/>
    <child link="R_thumb_tip"/>
    <origin  xyz="0.015 0.013 -0.004"/>
  </joint>

  <link name="R_index_proximal">
    <inertial>
      <origin xyz="0.0012 0.0119 -0.0060"/>
      <mass value="0.0042"/>
      <inertia ixx="6.6232E-07" ixy="-1.5775E-08" ixz="1.8515E-12" iyy="2.1146E-07" iyz="-5.0828E-12" izz="6.9398E-07"/>
    </inertial>
    <visual>
      <geometry>
        <mesh filename="../meshes/inspire_hand/Link15_r.STL"/>
      </geometry>
      <material name="">
        <color rgba="1 1 1 1"/>
      </material>
    </visual>
  </link>

  <joint name="R_index_proximal_joint" type="fixed">
    <origin xyz="0.0323 0.0003 -0.1365" rpy="-1.5359 0 -1.5708"/>
    <parent link="R_hand_base_link"/>
    <child link="R_index_proximal"/>
    <axis xyz="0 0 1"/>
    <limit lower="0" upper="1.7" effort="1" velocity="0.5"/>
  </joint>

  <link name="R_index_intermediate">
    <inertial>
      <origin xyz="0.0020 0.0196 -0.005"/>
      <mass value="0.0046"/>
      <inertia ixx="7.6111E-07" ixy="8.7637E-08" ixz="-3.7751E-13" iyy="9.6076E-08" iyz="9.9444E-13" izz="7.8179E-07"/>
    </inertial>
    <visual>
      <geometry>
        <mesh filename="../meshes/inspire_hand/Link16_r.STL"/>
      </geometry>
      <material name="">
        <color rgba="1 1 1 1"/>
      </material>
    </visual>
  </link>

  <joint name="R_index_intermediate_joint" type="fixed">
    <origin xyz="-0.0026 0.0320 -0.001"/>
    <parent link="R_index_proximal"/>
    <child link="R_index_intermediate"/>
    <axis xyz="0 0 1"/>
    <limit lower="0" upper="1.7" effort="1" velocity="0.5"/>
    <mimic joint="R_index_proximal_joint" multiplier="1" offset="0"/>
  </joint>

  <link name="R_index_tip">
    <inertial>
      <origin xyz="0 0 0"/>
      <mass value="0.006"/>
      <inertia ixx="1E-8" ixy="1E-12" ixz="1E-12" iyy="1E-8" iyz="1E-12" izz="1E-8"/>
    </inertial>
    <visual>
      <geometry>
        <sphere radius="0.005"/>
      </geometry>
      <material name="green">
        <color rgba="0 1 0 1"/>
      </material>
    </visual>
  </link>
  
  <joint name="R_index_tip_joint" type="fixed">
    <parent link="R_index_intermediate"/>
    <child link="R_index_tip"/>
    <origin  xyz="-0.005 0.04 -0.004"/>
  </joint>

  <link name="R_middle_proximal">
    <inertial>
      <origin xyz="0.0013 0.0119 -0.0060"/>
      <mass value="0.0042"/>
      <inertia ixx="6.6211E-07" ixy="-1.8461E-08" ixz="1.8002E-12" iyy="2.1167E-07" iyz="-6.6808E-12" izz="6.9397E-07"/>
    </inertial>
    <visual>
      <geometry>
        <mesh filename="../meshes/inspire_hand/Link17_r.STL"/>
      </geometry>
      <material name="">
        <color rgba="1 1 1 1"/>
      </material>
    </visual>
  </link>

  <joint name="R_middle_proximal_joint" type="fixed">
    <origin xyz="0.0129 0.0003 -0.1371" rpy="-1.5708 0 -1.5708"/>
    <parent link="R_hand_base_link"/>
    <child link="R_middle_proximal"/>
    <axis xyz="0 0 1"/>
    <limit lower="0" upper="1.7" effort="1" velocity="0.5"/>
  </joint>

  <link name="R_middle_intermediate">
    <inertial>
      <origin xyz="0.0019 0.0208 -0.005"/>
      <mass value="0.0050"/>
      <inertia ixx="9.5822E-07" ixy="1.1425E-07" ixz="-2.4791E-12" iyy="1.0646E-07" iyz="5.9173E-12" izz="9.8384E-07"/>
    </inertial>
    <visual>
      <geometry>
        <mesh filename="../meshes/inspire_hand/Link18_r.STL"/>
      </geometry>
      <material name="">
        <color rgba="1 1 1 1"/>
      </material>
    </visual>
  </link>

  <joint name="R_middle_intermediate_joint" type="fixed">
    <origin xyz="-0.0024 0.0320 -0.001"/>
    <parent link="R_middle_proximal"/>
    <child link="R_middle_intermediate"/>
    <axis xyz="0 0 1"/>
    <limit lower="0" upper="1.7" effort="1" velocity="0.5"/>
    <mimic joint="R_middle_proximal_joint" multiplier="1" offset="0"/>
  </joint>
  
  <link name="R_middle_tip">
    <inertial>
      <origin xyz="0 0 0"/>
      <mass value="0.006"/>
      <inertia ixx="1E-8" ixy="1E-12" ixz="1E-12" iyy="1E-8" iyz="1E-12" izz="1E-8"/>
    </inertial>
    <visual>
      <geometry>
        <sphere radius="0.005"/>
      </geometry>
      <material name="green">
        <color rgba="0 1 0 1"/>
      </material>
    </visual>
  </link>
  
  <joint name="R_middle_tip_joint" type="fixed">
    <parent link="R_middle_intermediate"/>
    <child link="R_middle_tip"/>
    <origin  xyz="-0.005 0.045 -0.004"/>
  </joint>
  
  <link name="R_ring_proximal">
    <inertial>
      <origin xyz="0.0013 0.0119 -0.0060"/>
      <mass value="0.0042"/>
      <inertia ixx="6.6211E-07" ixy="-1.8461E-08" ixz="1.5793E-12" iyy="2.1167E-07" iyz="-6.6868E-12" izz="6.9397E-07"/>
    </inertial>
    <visual>
      <geometry>
        <mesh filename="../meshes/inspire_hand/Link19_r.STL"/>
      </geometry>
      <material name="">
        <color rgba="1 1 1 1"/>
      </material>
    </visual>
  </link>

  <joint name="R_ring_proximal_joint" type="fixed">
    <origin xyz="-0.0063 0.0003 -0.1369" rpy="-1.6232 0 -1.5708"/>
    <parent link="R_hand_base_link"/>
    <child link="R_ring_proximal"/>
    <axis xyz="0 0 1"/>
    <limit lower="0" upper="1.7" effort="1" velocity="0.5"/>
  </joint>

  <link name="R_ring_intermediate">
    <inertial>
      <origin xyz="0.0022 0.0196 -0.005"/>
      <mass value="0.0046"/>
      <inertia ixx="7.6286E-07" ixy="8.0635E-08" ixz="-6.1562E-13" iyy="9.431E-08" iyz="5.8619E-13" izz="7.8177E-07"/>
    </inertial>
    <visual>
      <geometry>
        <mesh filename="../meshes/inspire_hand/Link20_r.STL"/>
      </geometry>
      <material name="">
        <color rgba="1 1 1 1"/>
      </material>
    </visual>
  </link>

  <joint name="R_ring_intermediate_joint" type="fixed">
    <origin xyz="-0.0024 0.0320 -0.001"/>
    <parent link="R_ring_proximal"/>
    <child link="R_ring_intermediate"/>
    <axis xyz="0 0 1"/>
    <limit lower="0" upper="1.7" effort="1" velocity="0.5"/>
    <mimic joint="R_ring_proximal_joint" multiplier="1" offset="0"/>
  </joint>

  <link name="R_ring_tip">
    <inertial>
      <origin xyz="0 0 0"/>
      <mass value="0.006"/>
      <inertia ixx="1E-8" ixy="1E-12" ixz="1E-12" iyy="1E-8" iyz="1E-12" izz="1E-8"/>
    </inertial>
    <visual>
      <geometry>
        <sphere radius="0.005"/>
      </geometry>
    </visual>
  </link>
  
  <joint name="R_ring_tip_joint" type="fixed">
    <parent link="R_ring_intermediate"/>
    <child link="R_ring_tip"/>
    <origin  xyz="-0.002 0.04 -0.004"/>
  </joint>
  
  <link name="R_pinky_proximal">
    <inertial>
      <origin xyz="0.0013 0.0119 -0.0060"/>
      <mass value="0.0042"/>
      <inertia ixx="6.6211E-07" ixy="-1.8461E-08" ixz="1.6907E-12" iyy="2.1167E-07" iyz="-6.9334E-12" izz="6.9397E-07"/>
    </inertial>
    <visual>
      <geometry>
        <mesh filename="../meshes/inspire_hand/Link21_r.STL"/>
      </geometry>
    </visual>
  </link>

  <joint name="R_pinky_proximal_joint" type="fixed">
    <origin xyz="-0.0255 0.0003 -0.1357" rpy="-1.6739 0 -1.5708"/>
    <parent link="R_hand_base_link"/>
    <child link="R_pinky_proximal"/>
    <axis xyz="0 0 1"/>
    <limit lower="0" upper="1.7" effort="1" velocity="0.5"/>
  </joint>

  <link name="R_pinky_intermediate">
    <inertial>
      <origin xyz="0.0025 0.0162 -0.0050"/>
      <mass value="0.0036"/>
      <inertia ixx="4.3913E-07" ixy="4.1418E-08" ixz="3.7168E-11" iyy="7.0247E-08" iyz="5.8613E-11" izz="4.4867E-07"/>
    </inertial>
    <visual>
      <geometry>
        <mesh filename="../meshes/inspire_hand/Link22_r.STL"/>
      </geometry>
    </visual>
  </link>

  <joint name="R_pinky_intermediate_joint" type="fixed">
    <origin xyz="-0.0024 0.0320 -0.001"/>
    <parent link="R_pinky_proximal"/>
    <child link="R_pinky_intermediate"/>
    <axis xyz="0 0 1"/>
    <limit lower="0" upper="1.7" effort="1" velocity="0.5"/>
    <mimic joint="R_pinky_proximal_joint" multiplier="1" offset="0"/>
  </joint>
  
  <link name="R_pinky_tip">
    <inertial>
      <origin xyz="0 0 0"/>
      <mass value="0.006"/>
      <inertia ixx="1E-8" ixy="1E-12" ixz="1E-12" iyy="1E-8" iyz="1E-12" izz="1E-8"/>
    </inertial>
    <visual>
      <geometry>
        <sphere radius="0.005"/>
      </geometry>
      <material name="green">
        <color rgba="0 1 0 1"/>
      </material>
    </visual>
  </link>

  <joint name="R_pinky_tip_joint" type="fixed">
    <parent link="R_pinky_intermediate"/>
    <child link="R_pinky_tip"/>
    <origin  xyz="-0.002 0.032 -0.004"/>
  </joint>

  <link name="head_roll_link">
    <inertial>
      <origin xyz="0.0043 0 0"/>
      <mass value="0.01"/>
      <inertia ixx="4.3E-7" ixy="0" ixz="0" iyy="4.4E-7" iyz="0" izz="7.2E-7"/>
    </inertial>
    <visual>
      <geometry>
        <mesh filename="../meshes/head_roll_link.STL"/>
      </geometry>
    </visual>
  </link>

  <joint name="head_roll_joint" type="fixed">
    <origin xyz="0.002 0.0005 0.1447"/>
    <parent link="torso_link"/>
    <child link="head_roll_link"/>
    <axis xyz="1 0 0"/>
    <limit lower="-0.35" upper="0.35" effort="3.95" velocity="27.96"/>
  </joint>
  
  <link name="head_pitch_link">
    <inertial>
      <origin xyz="-0.0022 -4.1784E-07 0.0175"/>
      <mass value="0.06"/>
      <inertia ixx="2.509E-05" ixy="0" ixz="-1.3E-06" iyy="1.707E-05" iyz="0" izz="2.462E-05"/>
    </inertial>
    <visual>
      <geometry>
        <mesh filename="../meshes/head_pitch_link.STL"/>
      </geometry>
      <material name="">
        <color rgba="0.7529 0.7529 0.7529 1"/>
      </material>
    </visual>
  </link>

  <joint name="head_pitch_joint" type="fixed">
    <parent link="head_roll_link"/>
    <child link="head_pitch_link"/>
    <axis xyz="0 1 0"/>
    <limit lower="-0.87" upper="0.87" effort="3.95" velocity="27.96"/>
  </joint>
  
  <link name="head_yaw_link">
    <inertial>
      <origin xyz="0.0271 -0.0021 0.0958"/>
      <mass value="1.58"/>
      <inertia ixx="7.5444E-3" ixy="7.210E-5" ixz="9.5183E-4" iyy="0.0101" iyz="5.051E-5" izz="5.6597E-3"/>
    </inertial>
    <visual>
      <geometry>
        <mesh filename="../meshes/head_yaw_link.STL"/>
      </geometry>
    </visual>
    <collision name="head_yaw_link.STL">
      <origin xyz="0.0183 -0.0009 0.0936"/>
      <geometry>
        <sphere radius="0.1187"/>
      </geometry>
    </collision>
  </link>
  
  <joint name="head_yaw_joint" type="fixed">
    <origin xyz="0 0 0.0513"/>
    <parent link="head_pitch_link"/>
    <child link="head_yaw_link"/>
    <axis xyz="0 0 1"/>
    <limit lower="-2.71" upper="2.71" effort="3.95" velocity="27.96"/>
  </joint>
  
  <link name="imu_link">
    <inertial>
      <origin xyz="-0.0621 -1.5129E-06 -0.0031"/>
      <mass value="0.05"/>
      <inertia ixx="1.125E-05" ixy="0" ixz="8.8E-07" iyy="1.67E-05" iyz="0" izz="1.983E-05"/>
    </inertial>
    <visual>
      <geometry>
        <mesh filename="../meshes/imu_link.STL"/>
      </geometry>
    </visual>
  </link>

  <joint name="imu_joint" type="fixed">
    <origin xyz="0 0 -0.0596"/>
    <parent link="base_link"/>
    <child link="imu_link"/>
  </joint>
  
</robot>